2020-01-05 09:49:03,586: OSError: write error
2020-01-05 09:49:04,422: OSError: write error
2020-01-05 09:50:22,137: OSError: write error
2020-01-05 10:08:52,924: OSError: write error
2020-01-05 10:08:56,002: OSError: write error
2020-01-05 10:26:06,725: OSError: write error
2020-01-05 10:37:40,194: OSError: write error
2020-01-05 10:38:59,216: OSError: write error
2020-01-05 10:59:47,090: OSError: write error
2020-01-05 11:27:48,905: OSError: write error
2020-01-05 11:49:05,455: OSError: write error
2020-01-05 12:07:22,584: OSError: write error
2020-01-05 12:22:18,162: OSError: write error
2020-01-05 12:22:19,226: OSError: write error
2020-01-05 12:22:21,228: OSError: write error
2020-01-05 12:22:22,558: OSError: write error
2020-01-05 12:22:24,775: OSError: write error
2020-01-05 12:22:24,812: OSError: write error
2020-01-05 12:22:58,806: OSError: write error
2020-01-05 12:34:38,845: OSError: write error
2020-01-05 12:51:05,332: OSError: write error
2020-01-05 13:02:40,006: OSError: write error
2020-01-05 13:27:43,201: OSError: write error
2020-01-05 13:27:43,241: OSError: write error
2020-01-05 13:27:43,277: OSError: write error
2020-01-05 13:27:43,974: OSError: write error
2020-01-05 13:49:12,492: OSError: write error
2020-01-05 14:09:36,283: Exception on /college/2019/UG/MECH [GET]
Traceback (most recent call last):
  File "/usr/lib/python3.7/site-packages/flask/app.py", line 2292, in wsgi_app
    response = self.full_dispatch_request()
  File "/usr/lib/python3.7/site-packages/flask/app.py", line 1815, in full_dispatch_request
    rv = self.handle_user_exception(e)
  File "/usr/lib/python3.7/site-packages/flask_restful/__init__.py", line 273, in error_router
    return original_handler(e)
  File "/usr/lib/python3.7/site-packages/flask/app.py", line 1718, in handle_user_exception
    reraise(exc_type, exc_value, tb)
  File "/usr/lib/python3.7/site-packages/flask/_compat.py", line 35, in reraise
    raise value
  File "/usr/lib/python3.7/site-packages/flask/app.py", line 1813, in full_dispatch_request
    rv = self.dispatch_request()
  File "/usr/lib/python3.7/site-packages/flask/app.py", line 1799, in dispatch_request
    return self.view_functions[rule.endpoint](**req.view_args)
  File "/home/nilekrator/resultportal/extensions.py", line 12, in decorated_function
    return f(*args, **kwargs)
  File "/home/nilekrator/resultportal/student/college.py", line 66, in collegerank
    semester = cursor.fetchone()[0]
TypeError: 'NoneType' object is not subscriptable
2020-01-05 14:10:05,221: Exception on /college/2019/UG/MECH [GET]
Traceback (most recent call last):
  File "/usr/lib/python3.7/site-packages/flask/app.py", line 2292, in wsgi_app
    response = self.full_dispatch_request()
  File "/usr/lib/python3.7/site-packages/flask/app.py", line 1815, in full_dispatch_request
    rv = self.handle_user_exception(e)
  File "/usr/lib/python3.7/site-packages/flask_restful/__init__.py", line 273, in error_router
    return original_handler(e)
  File "/usr/lib/python3.7/site-packages/flask/app.py", line 1718, in handle_user_exception
    reraise(exc_type, exc_value, tb)
  File "/usr/lib/python3.7/site-packages/flask/_compat.py", line 35, in reraise
    raise value
  File "/usr/lib/python3.7/site-packages/flask/app.py", line 1813, in full_dispatch_request
    rv = self.dispatch_request()
  File "/usr/lib/python3.7/site-packages/flask/app.py", line 1799, in dispatch_request
    return self.view_functions[rule.endpoint](**req.view_args)
  File "/home/nilekrator/resultportal/extensions.py", line 12, in decorated_function
    return f(*args, **kwargs)
  File "/home/nilekrator/resultportal/student/college.py", line 66, in collegerank
    semester = cursor.fetchone()[0]
TypeError: 'NoneType' object is not subscriptable
2020-01-05 14:10:34,732: Exception on /college/2019/UG/MECH [GET]
Traceback (most recent call last):
  File "/usr/lib/python3.7/site-packages/flask/app.py", line 2292, in wsgi_app
    response = self.full_dispatch_request()
  File "/usr/lib/python3.7/site-packages/flask/app.py", line 1815, in full_dispatch_request
    rv = self.handle_user_exception(e)
  File "/usr/lib/python3.7/site-packages/flask_restful/__init__.py", line 273, in error_router
    return original_handler(e)
  File "/usr/lib/python3.7/site-packages/flask/app.py", line 1718, in handle_user_exception
    reraise(exc_type, exc_value, tb)
  File "/usr/lib/python3.7/site-packages/flask/_compat.py", line 35, in reraise
    raise value
  File "/usr/lib/python3.7/site-packages/flask/app.py", line 1813, in full_dispatch_request
    rv = self.dispatch_request()
  File "/usr/lib/python3.7/site-packages/flask/app.py", line 1799, in dispatch_request
    return self.view_functions[rule.endpoint](**req.view_args)
  File "/home/nilekrator/resultportal/extensions.py", line 12, in decorated_function
    return f(*args, **kwargs)
  File "/home/nilekrator/resultportal/student/college.py", line 66, in collegerank
    semester = cursor.fetchone()[0]
TypeError: 'NoneType' object is not subscriptable
2020-01-05 14:10:45,322: Exception on /college/2019/UG/MECH [GET]
Traceback (most recent call last):
  File "/usr/lib/python3.7/site-packages/flask/app.py", line 2292, in wsgi_app
    response = self.full_dispatch_request()
  File "/usr/lib/python3.7/site-packages/flask/app.py", line 1815, in full_dispatch_request
    rv = self.handle_user_exception(e)
  File "/usr/lib/python3.7/site-packages/flask_restful/__init__.py", line 273, in error_router
    return original_handler(e)
  File "/usr/lib/python3.7/site-packages/flask/app.py", line 1718, in handle_user_exception
    reraise(exc_type, exc_value, tb)
  File "/usr/lib/python3.7/site-packages/flask/_compat.py", line 35, in reraise
    raise value
  File "/usr/lib/python3.7/site-packages/flask/app.py", line 1813, in full_dispatch_request
    rv = self.dispatch_request()
  File "/usr/lib/python3.7/site-packages/flask/app.py", line 1799, in dispatch_request
    return self.view_functions[rule.endpoint](**req.view_args)
  File "/home/nilekrator/resultportal/extensions.py", line 12, in decorated_function
    return f(*args, **kwargs)
  File "/home/nilekrator/resultportal/student/college.py", line 66, in collegerank
    semester = cursor.fetchone()[0]
TypeError: 'NoneType' object is not subscriptable
2020-01-05 14:21:10,020: Exception on /rank [GET]
Traceback (most recent call last):
  File "/usr/lib/python3.7/site-packages/flask/app.py", line 2292, in wsgi_app
    response = self.full_dispatch_request()
  File "/usr/lib/python3.7/site-packages/flask/app.py", line 1815, in full_dispatch_request
    rv = self.handle_user_exception(e)
  File "/usr/lib/python3.7/site-packages/flask_restful/__init__.py", line 273, in error_router
    return original_handler(e)
  File "/usr/lib/python3.7/site-packages/flask/app.py", line 1718, in handle_user_exception
    reraise(exc_type, exc_value, tb)
  File "/usr/lib/python3.7/site-packages/flask/_compat.py", line 35, in reraise
    raise value
  File "/usr/lib/python3.7/site-packages/flask/app.py", line 1813, in full_dispatch_request
    rv = self.dispatch_request()
  File "/usr/lib/python3.7/site-packages/flask/app.py", line 1799, in dispatch_request
    return self.view_functions[rule.endpoint](**req.view_args)
  File "/home/nilekrator/resultportal/extensions.py", line 12, in decorated_function
    return f(*args, **kwargs)
  File "/home/nilekrator/resultportal/student/student.py", line 219, in rank
    Stu.get_raw_rank()
  File "/home/nilekrator/resultportal/student/studentrank.py", line 39, in get_raw_rank
    method=self.method,
  File "/home/nilekrator/.local/lib/python3.7/site-packages/pymysql/cursors.py", line 170, in execute
    result = self._query(query)
  File "/home/nilekrator/.local/lib/python3.7/site-packages/pymysql/cursors.py", line 328, in _query
    conn.query(q)
  File "/home/nilekrator/.local/lib/python3.7/site-packages/pymysql/connections.py", line 517, in query
    self._affected_rows = self._read_query_result(unbuffered=unbuffered)
  File "/home/nilekrator/.local/lib/python3.7/site-packages/pymysql/connections.py", line 732, in _read_query_result
    result.read()
  File "/home/nilekrator/.local/lib/python3.7/site-packages/pymysql/connections.py", line 1075, in read
    first_packet = self.connection._read_packet()
  File "/home/nilekrator/.local/lib/python3.7/site-packages/pymysql/connections.py", line 684, in _read_packet
    packet.check_error()
  File "/home/nilekrator/.local/lib/python3.7/site-packages/pymysql/protocol.py", line 220, in check_error
    err.raise_mysql_exception(self._data)
  File "/home/nilekrator/.local/lib/python3.7/site-packages/pymysql/err.py", line 109, in raise_mysql_exception
    raise errorclass(errno, errval)
pymysql.err.ProgrammingError: (1146, "Table 'nilekrator$_2019.UG_MM_3' doesn't exist")
2020-01-05 14:21:21,514: Exception on /rank [GET]
Traceback (most recent call last):
  File "/usr/lib/python3.7/site-packages/flask/app.py", line 2292, in wsgi_app
    response = self.full_dispatch_request()
  File "/usr/lib/python3.7/site-packages/flask/app.py", line 1815, in full_dispatch_request
    rv = self.handle_user_exception(e)
  File "/usr/lib/python3.7/site-packages/flask_restful/__init__.py", line 273, in error_router
    return original_handler(e)
  File "/usr/lib/python3.7/site-packages/flask/app.py", line 1718, in handle_user_exception
    reraise(exc_type, exc_value, tb)
  File "/usr/lib/python3.7/site-packages/flask/_compat.py", line 35, in reraise
    raise value
  File "/usr/lib/python3.7/site-packages/flask/app.py", line 1813, in full_dispatch_request
    rv = self.dispatch_request()
  File "/usr/lib/python3.7/site-packages/flask/app.py", line 1799, in dispatch_request
    return self.view_functions[rule.endpoint](**req.view_args)
  File "/home/nilekrator/resultportal/extensions.py", line 12, in decorated_function
    return f(*args, **kwargs)
  File "/home/nilekrator/resultportal/student/student.py", line 219, in rank
    Stu.get_raw_rank()
  File "/home/nilekrator/resultportal/student/studentrank.py", line 39, in get_raw_rank
    method=self.method,
  File "/home/nilekrator/.local/lib/python3.7/site-packages/pymysql/cursors.py", line 170, in execute
    result = self._query(query)
  File "/home/nilekrator/.local/lib/python3.7/site-packages/pymysql/cursors.py", line 328, in _query
    conn.query(q)
  File "/home/nilekrator/.local/lib/python3.7/site-packages/pymysql/connections.py", line 517, in query
    self._affected_rows = self._read_query_result(unbuffered=unbuffered)
  File "/home/nilekrator/.local/lib/python3.7/site-packages/pymysql/connections.py", line 732, in _read_query_result
    result.read()
  File "/home/nilekrator/.local/lib/python3.7/site-packages/pymysql/connections.py", line 1075, in read
    first_packet = self.connection._read_packet()
  File "/home/nilekrator/.local/lib/python3.7/site-packages/pymysql/connections.py", line 684, in _read_packet
    packet.check_error()
  File "/home/nilekrator/.local/lib/python3.7/site-packages/pymysql/protocol.py", line 220, in check_error
    err.raise_mysql_exception(self._data)
  File "/home/nilekrator/.local/lib/python3.7/site-packages/pymysql/err.py", line 109, in raise_mysql_exception
    raise errorclass(errno, errval)
pymysql.err.ProgrammingError: (1146, "Table 'nilekrator$_2019.UG_CE_3' doesn't exist")
2020-01-05 14:21:29,955: Exception on /rank [GET]
Traceback (most recent call last):
  File "/usr/lib/python3.7/site-packages/flask/app.py", line 2292, in wsgi_app
    response = self.full_dispatch_request()
  File "/usr/lib/python3.7/site-packages/flask/app.py", line 1815, in full_dispatch_request
    rv = self.handle_user_exception(e)
  File "/usr/lib/python3.7/site-packages/flask_restful/__init__.py", line 273, in error_router
    return original_handler(e)
  File "/usr/lib/python3.7/site-packages/flask/app.py", line 1718, in handle_user_exception
    reraise(exc_type, exc_value, tb)
  File "/usr/lib/python3.7/site-packages/flask/_compat.py", line 35, in reraise
    raise value
  File "/usr/lib/python3.7/site-packages/flask/app.py", line 1813, in full_dispatch_request
    rv = self.dispatch_request()
  File "/usr/lib/python3.7/site-packages/flask/app.py", line 1799, in dispatch_request
    return self.view_functions[rule.endpoint](**req.view_args)
  File "/home/nilekrator/resultportal/extensions.py", line 12, in decorated_function
    return f(*args, **kwargs)
  File "/home/nilekrator/resultportal/student/student.py", line 219, in rank
    Stu.get_raw_rank()
  File "/home/nilekrator/resultportal/student/studentrank.py", line 39, in get_raw_rank
    method=self.method,
  File "/home/nilekrator/.local/lib/python3.7/site-packages/pymysql/cursors.py", line 170, in execute
    result = self._query(query)
  File "/home/nilekrator/.local/lib/python3.7/site-packages/pymysql/cursors.py", line 328, in _query
    conn.query(q)
  File "/home/nilekrator/.local/lib/python3.7/site-packages/pymysql/connections.py", line 517, in query
    self._affected_rows = self._read_query_result(unbuffered=unbuffered)
  File "/home/nilekrator/.local/lib/python3.7/site-packages/pymysql/connections.py", line 732, in _read_query_result
    result.read()
  File "/home/nilekrator/.local/lib/python3.7/site-packages/pymysql/connections.py", line 1075, in read
    first_packet = self.connection._read_packet()
  File "/home/nilekrator/.local/lib/python3.7/site-packages/pymysql/connections.py", line 684, in _read_packet
    packet.check_error()
  File "/home/nilekrator/.local/lib/python3.7/site-packages/pymysql/protocol.py", line 220, in check_error
    err.raise_mysql_exception(self._data)
  File "/home/nilekrator/.local/lib/python3.7/site-packages/pymysql/err.py", line 109, in raise_mysql_exception
    raise errorclass(errno, errval)
pymysql.err.ProgrammingError: (1146, "Table 'nilekrator$_2019.UG_MM_3' doesn't exist")
2020-01-05 14:21:45,378: OSError: write error
2020-01-05 14:21:46,523: OSError: write error
2020-01-05 14:21:46,613: Exception on /rank [GET]
Traceback (most recent call last):
  File "/usr/lib/python3.7/site-packages/flask/app.py", line 2292, in wsgi_app
    response = self.full_dispatch_request()
  File "/usr/lib/python3.7/site-packages/flask/app.py", line 1815, in full_dispatch_request
    rv = self.handle_user_exception(e)
  File "/usr/lib/python3.7/site-packages/flask_restful/__init__.py", line 273, in error_router
    return original_handler(e)
  File "/usr/lib/python3.7/site-packages/flask/app.py", line 1718, in handle_user_exception
    reraise(exc_type, exc_value, tb)
  File "/usr/lib/python3.7/site-packages/flask/_compat.py", line 35, in reraise
    raise value
  File "/usr/lib/python3.7/site-packages/flask/app.py", line 1813, in full_dispatch_request
    rv = self.dispatch_request()
  File "/usr/lib/python3.7/site-packages/flask/app.py", line 1799, in dispatch_request
    return self.view_functions[rule.endpoint](**req.view_args)
  File "/home/nilekrator/resultportal/extensions.py", line 12, in decorated_function
    return f(*args, **kwargs)
  File "/home/nilekrator/resultportal/student/student.py", line 219, in rank
    Stu.get_raw_rank()
  File "/home/nilekrator/resultportal/student/studentrank.py", line 39, in get_raw_rank
    method=self.method,
  File "/home/nilekrator/.local/lib/python3.7/site-packages/pymysql/cursors.py", line 170, in execute
    result = self._query(query)
  File "/home/nilekrator/.local/lib/python3.7/site-packages/pymysql/cursors.py", line 328, in _query
    conn.query(q)
  File "/home/nilekrator/.local/lib/python3.7/site-packages/pymysql/connections.py", line 517, in query
    self._affected_rows = self._read_query_result(unbuffered=unbuffered)
  File "/home/nilekrator/.local/lib/python3.7/site-packages/pymysql/connections.py", line 732, in _read_query_result
    result.read()
  File "/home/nilekrator/.local/lib/python3.7/site-packages/pymysql/connections.py", line 1075, in read
    first_packet = self.connection._read_packet()
  File "/home/nilekrator/.local/lib/python3.7/site-packages/pymysql/connections.py", line 684, in _read_packet
    packet.check_error()
  File "/home/nilekrator/.local/lib/python3.7/site-packages/pymysql/protocol.py", line 220, in check_error
    err.raise_mysql_exception(self._data)
  File "/home/nilekrator/.local/lib/python3.7/site-packages/pymysql/err.py", line 109, in raise_mysql_exception
    raise errorclass(errno, errval)
pymysql.err.ProgrammingError: (1146, "Table 'nilekrator$_2019.UG_MM_2' doesn't exist")
2020-01-05 14:27:02,080: Exception on /rank [GET]
Traceback (most recent call last):
  File "/usr/lib/python3.7/site-packages/flask/app.py", line 2292, in wsgi_app
    response = self.full_dispatch_request()
  File "/usr/lib/python3.7/site-packages/flask/app.py", line 1815, in full_dispatch_request
    rv = self.handle_user_exception(e)
  File "/usr/lib/python3.7/site-packages/flask_restful/__init__.py", line 273, in error_router
    return original_handler(e)
  File "/usr/lib/python3.7/site-packages/flask/app.py", line 1718, in handle_user_exception
    reraise(exc_type, exc_value, tb)
  File "/usr/lib/python3.7/site-packages/flask/_compat.py", line 35, in reraise
    raise value
  File "/usr/lib/python3.7/site-packages/flask/app.py", line 1813, in full_dispatch_request
    rv = self.dispatch_request()
  File "/usr/lib/python3.7/site-packages/flask/app.py", line 1799, in dispatch_request
    return self.view_functions[rule.endpoint](**req.view_args)
  File "/home/nilekrator/resultportal/extensions.py", line 12, in decorated_function
    return f(*args, **kwargs)
  File "/home/nilekrator/resultportal/student/student.py", line 219, in rank
    Stu.get_raw_rank()
  File "/home/nilekrator/resultportal/student/studentrank.py", line 39, in get_raw_rank
    method=self.method,
  File "/home/nilekrator/.local/lib/python3.7/site-packages/pymysql/cursors.py", line 170, in execute
    result = self._query(query)
  File "/home/nilekrator/.local/lib/python3.7/site-packages/pymysql/cursors.py", line 328, in _query
    conn.query(q)
  File "/home/nilekrator/.local/lib/python3.7/site-packages/pymysql/connections.py", line 517, in query
    self._affected_rows = self._read_query_result(unbuffered=unbuffered)
  File "/home/nilekrator/.local/lib/python3.7/site-packages/pymysql/connections.py", line 732, in _read_query_result
    result.read()
  File "/home/nilekrator/.local/lib/python3.7/site-packages/pymysql/connections.py", line 1075, in read
    first_packet = self.connection._read_packet()
  File "/home/nilekrator/.local/lib/python3.7/site-packages/pymysql/connections.py", line 684, in _read_packet
    packet.check_error()
  File "/home/nilekrator/.local/lib/python3.7/site-packages/pymysql/protocol.py", line 220, in check_error
    err.raise_mysql_exception(self._data)
  File "/home/nilekrator/.local/lib/python3.7/site-packages/pymysql/err.py", line 109, in raise_mysql_exception
    raise errorclass(errno, errval)
pymysql.err.ProgrammingError: (1146, "Table 'nilekrator$_2019.UG_MM_2' doesn't exist")
2020-01-05 14:51:00,277: OSError: write error
2020-01-05 14:51:00,700: OSError: write error
2020-01-05 14:51:43,859: OSError: write error
2020-01-05 15:06:30,028: OSError: write error
2020-01-05 16:27:51,551: OSError: write error
2020-01-05 16:27:53,168: OSError: write error
2020-01-05 16:32:08,350: OSError: write error
2020-01-05 16:37:36,474: OSError: write error
2020-01-05 17:44:57,600: OSError: write error
2020-01-05 18:16:11,341: OSError: write error
2020-01-05 18:32:02,205: OSError: write error
2020-01-05 18:53:40,138: OSError: write error
2020-01-05 18:56:43,500: OSError: write error
2020-01-05 19:37:46,108: OSError: write error
2020-01-05 20:40:01,113: Exception on /rank [GET]
Traceback (most recent call last):
  File "/usr/lib/python3.7/site-packages/flask/app.py", line 2292, in wsgi_app
    response = self.full_dispatch_request()
  File "/usr/lib/python3.7/site-packages/flask/app.py", line 1815, in full_dispatch_request
    rv = self.handle_user_exception(e)
  File "/usr/lib/python3.7/site-packages/flask_restful/__init__.py", line 273, in error_router
    return original_handler(e)
  File "/usr/lib/python3.7/site-packages/flask/app.py", line 1718, in handle_user_exception
    reraise(exc_type, exc_value, tb)
  File "/usr/lib/python3.7/site-packages/flask/_compat.py", line 35, in reraise
    raise value
  File "/usr/lib/python3.7/site-packages/flask/app.py", line 1813, in full_dispatch_request
    rv = self.dispatch_request()
  File "/usr/lib/python3.7/site-packages/flask/app.py", line 1799, in dispatch_request
    return self.view_functions[rule.endpoint](**req.view_args)
  File "/home/nilekrator/resultportal/extensions.py", line 12, in decorated_function
    return f(*args, **kwargs)
  File "/home/nilekrator/resultportal/student/student.py", line 219, in rank
    Stu.get_raw_rank()
  File "/home/nilekrator/resultportal/student/studentrank.py", line 39, in get_raw_rank
    method=self.method,
  File "/home/nilekrator/.local/lib/python3.7/site-packages/pymysql/cursors.py", line 170, in execute
    result = self._query(query)
  File "/home/nilekrator/.local/lib/python3.7/site-packages/pymysql/cursors.py", line 328, in _query
    conn.query(q)
  File "/home/nilekrator/.local/lib/python3.7/site-packages/pymysql/connections.py", line 517, in query
    self._affected_rows = self._read_query_result(unbuffered=unbuffered)
  File "/home/nilekrator/.local/lib/python3.7/site-packages/pymysql/connections.py", line 732, in _read_query_result
    result.read()
  File "/home/nilekrator/.local/lib/python3.7/site-packages/pymysql/connections.py", line 1075, in read
    first_packet = self.connection._read_packet()
  File "/home/nilekrator/.local/lib/python3.7/site-packages/pymysql/connections.py", line 684, in _read_packet
    packet.check_error()
  File "/home/nilekrator/.local/lib/python3.7/site-packages/pymysql/protocol.py", line 220, in check_error
    err.raise_mysql_exception(self._data)
  File "/home/nilekrator/.local/lib/python3.7/site-packages/pymysql/err.py", line 109, in raise_mysql_exception
    raise errorclass(errno, errval)
pymysql.err.ProgrammingError: (1146, "Table 'nilekrator$_2019.UG_ME_3' doesn't exist")
2020-01-05 20:40:03,292: Exception on /rank [GET]
Traceback (most recent call last):
  File "/usr/lib/python3.7/site-packages/flask/app.py", line 2292, in wsgi_app
    response = self.full_dispatch_request()
  File "/usr/lib/python3.7/site-packages/flask/app.py", line 1815, in full_dispatch_request
    rv = self.handle_user_exception(e)
  File "/usr/lib/python3.7/site-packages/flask_restful/__init__.py", line 273, in error_router
    return original_handler(e)
  File "/usr/lib/python3.7/site-packages/flask/app.py", line 1718, in handle_user_exception
    reraise(exc_type, exc_value, tb)
  File "/usr/lib/python3.7/site-packages/flask/_compat.py", line 35, in reraise
    raise value
  File "/usr/lib/python3.7/site-packages/flask/app.py", line 1813, in full_dispatch_request
    rv = self.dispatch_request()
  File "/usr/lib/python3.7/site-packages/flask/app.py", line 1799, in dispatch_request
    return self.view_functions[rule.endpoint](**req.view_args)
  File "/home/nilekrator/resultportal/extensions.py", line 12, in decorated_function
    return f(*args, **kwargs)
  File "/home/nilekrator/resultportal/student/student.py", line 219, in rank
    Stu.get_raw_rank()
  File "/home/nilekrator/resultportal/student/studentrank.py", line 39, in get_raw_rank
    method=self.method,
  File "/home/nilekrator/.local/lib/python3.7/site-packages/pymysql/cursors.py", line 170, in execute
    result = self._query(query)
  File "/home/nilekrator/.local/lib/python3.7/site-packages/pymysql/cursors.py", line 328, in _query
    conn.query(q)
  File "/home/nilekrator/.local/lib/python3.7/site-packages/pymysql/connections.py", line 517, in query
    self._affected_rows = self._read_query_result(unbuffered=unbuffered)
  File "/home/nilekrator/.local/lib/python3.7/site-packages/pymysql/connections.py", line 732, in _read_query_result
    result.read()
  File "/home/nilekrator/.local/lib/python3.7/site-packages/pymysql/connections.py", line 1075, in read
    first_packet = self.connection._read_packet()
  File "/home/nilekrator/.local/lib/python3.7/site-packages/pymysql/connections.py", line 684, in _read_packet
    packet.check_error()
  File "/home/nilekrator/.local/lib/python3.7/site-packages/pymysql/protocol.py", line 220, in check_error
    err.raise_mysql_exception(self._data)
  File "/home/nilekrator/.local/lib/python3.7/site-packages/pymysql/err.py", line 109, in raise_mysql_exception
    raise errorclass(errno, errval)
pymysql.err.ProgrammingError: (1146, "Table 'nilekrator$_2019.UG_ME_3' doesn't exist")
2020-01-05 20:40:07,489: Exception on /rank [GET]
Traceback (most recent call last):
  File "/usr/lib/python3.7/site-packages/flask/app.py", line 2292, in wsgi_app
    response = self.full_dispatch_request()
  File "/usr/lib/python3.7/site-packages/flask/app.py", line 1815, in full_dispatch_request
    rv = self.handle_user_exception(e)
  File "/usr/lib/python3.7/site-packages/flask_restful/__init__.py", line 273, in error_router
    return original_handler(e)
  File "/usr/lib/python3.7/site-packages/flask/app.py", line 1718, in handle_user_exception
    reraise(exc_type, exc_value, tb)
  File "/usr/lib/python3.7/site-packages/flask/_compat.py", line 35, in reraise
    raise value
  File "/usr/lib/python3.7/site-packages/flask/app.py", line 1813, in full_dispatch_request
    rv = self.dispatch_request()
  File "/usr/lib/python3.7/site-packages/flask/app.py", line 1799, in dispatch_request
    return self.view_functions[rule.endpoint](**req.view_args)
  File "/home/nilekrator/resultportal/extensions.py", line 12, in decorated_function
    return f(*args, **kwargs)
  File "/home/nilekrator/resultportal/student/student.py", line 219, in rank
    Stu.get_raw_rank()
  File "/home/nilekrator/resultportal/student/studentrank.py", line 39, in get_raw_rank
    method=self.method,
  File "/home/nilekrator/.local/lib/python3.7/site-packages/pymysql/cursors.py", line 170, in execute
    result = self._query(query)
  File "/home/nilekrator/.local/lib/python3.7/site-packages/pymysql/cursors.py", line 328, in _query
    conn.query(q)
  File "/home/nilekrator/.local/lib/python3.7/site-packages/pymysql/connections.py", line 517, in query
    self._affected_rows = self._read_query_result(unbuffered=unbuffered)
  File "/home/nilekrator/.local/lib/python3.7/site-packages/pymysql/connections.py", line 732, in _read_query_result
    result.read()
  File "/home/nilekrator/.local/lib/python3.7/site-packages/pymysql/connections.py", line 1075, in read
    first_packet = self.connection._read_packet()
  File "/home/nilekrator/.local/lib/python3.7/site-packages/pymysql/connections.py", line 684, in _read_packet
    packet.check_error()
  File "/home/nilekrator/.local/lib/python3.7/site-packages/pymysql/protocol.py", line 220, in check_error
    err.raise_mysql_exception(self._data)
  File "/home/nilekrator/.local/lib/python3.7/site-packages/pymysql/err.py", line 109, in raise_mysql_exception
    raise errorclass(errno, errval)
pymysql.err.ProgrammingError: (1146, "Table 'nilekrator$_2019.UG_ME_3' doesn't exist")
2020-01-05 20:40:11,040: Exception on /rank [GET]
Traceback (most recent call last):
  File "/usr/lib/python3.7/site-packages/flask/app.py", line 2292, in wsgi_app
    response = self.full_dispatch_request()
  File "/usr/lib/python3.7/site-packages/flask/app.py", line 1815, in full_dispatch_request
    rv = self.handle_user_exception(e)
  File "/usr/lib/python3.7/site-packages/flask_restful/__init__.py", line 273, in error_router
    return original_handler(e)
  File "/usr/lib/python3.7/site-packages/flask/app.py", line 1718, in handle_user_exception
    reraise(exc_type, exc_value, tb)
  File "/usr/lib/python3.7/site-packages/flask/_compat.py", line 35, in reraise
    raise value
  File "/usr/lib/python3.7/site-packages/flask/app.py", line 1813, in full_dispatch_request
    rv = self.dispatch_request()
  File "/usr/lib/python3.7/site-packages/flask/app.py", line 1799, in dispatch_request
    return self.view_functions[rule.endpoint](**req.view_args)
  File "/home/nilekrator/resultportal/extensions.py", line 12, in decorated_function
    return f(*args, **kwargs)
  File "/home/nilekrator/resultportal/student/student.py", line 219, in rank
    Stu.get_raw_rank()
  File "/home/nilekrator/resultportal/student/studentrank.py", line 39, in get_raw_rank
    method=self.method,
  File "/home/nilekrator/.local/lib/python3.7/site-packages/pymysql/cursors.py", line 170, in execute
    result = self._query(query)
  File "/home/nilekrator/.local/lib/python3.7/site-packages/pymysql/cursors.py", line 328, in _query
    conn.query(q)
  File "/home/nilekrator/.local/lib/python3.7/site-packages/pymysql/connections.py", line 517, in query
    self._affected_rows = self._read_query_result(unbuffered=unbuffered)
  File "/home/nilekrator/.local/lib/python3.7/site-packages/pymysql/connections.py", line 732, in _read_query_result
    result.read()
  File "/home/nilekrator/.local/lib/python3.7/site-packages/pymysql/connections.py", line 1075, in read
    first_packet = self.connection._read_packet()
  File "/home/nilekrator/.local/lib/python3.7/site-packages/pymysql/connections.py", line 684, in _read_packet
    packet.check_error()
  File "/home/nilekrator/.local/lib/python3.7/site-packages/pymysql/protocol.py", line 220, in check_error
    err.raise_mysql_exception(self._data)
  File "/home/nilekrator/.local/lib/python3.7/site-packages/pymysql/err.py", line 109, in raise_mysql_exception
    raise errorclass(errno, errval)
pymysql.err.ProgrammingError: (1146, "Table 'nilekrator$_2019.UG_ME_3' doesn't exist")
2020-01-05 20:43:34,582: Exception on /rank [GET]
Traceback (most recent call last):
  File "/usr/lib/python3.7/site-packages/flask/app.py", line 2292, in wsgi_app
    response = self.full_dispatch_request()
  File "/usr/lib/python3.7/site-packages/flask/app.py", line 1815, in full_dispatch_request
    rv = self.handle_user_exception(e)
  File "/usr/lib/python3.7/site-packages/flask_restful/__init__.py", line 273, in error_router
    return original_handler(e)
  File "/usr/lib/python3.7/site-packages/flask/app.py", line 1718, in handle_user_exception
    reraise(exc_type, exc_value, tb)
  File "/usr/lib/python3.7/site-packages/flask/_compat.py", line 35, in reraise
    raise value
  File "/usr/lib/python3.7/site-packages/flask/app.py", line 1813, in full_dispatch_request
    rv = self.dispatch_request()
  File "/usr/lib/python3.7/site-packages/flask/app.py", line 1799, in dispatch_request
    return self.view_functions[rule.endpoint](**req.view_args)
  File "/home/nilekrator/resultportal/extensions.py", line 12, in decorated_function
    return f(*args, **kwargs)
  File "/home/nilekrator/resultportal/student/student.py", line 219, in rank
    Stu.get_raw_rank()
  File "/home/nilekrator/resultportal/student/studentrank.py", line 39, in get_raw_rank
    method=self.method,
  File "/home/nilekrator/.local/lib/python3.7/site-packages/pymysql/cursors.py", line 170, in execute
    result = self._query(query)
  File "/home/nilekrator/.local/lib/python3.7/site-packages/pymysql/cursors.py", line 328, in _query
    conn.query(q)
  File "/home/nilekrator/.local/lib/python3.7/site-packages/pymysql/connections.py", line 517, in query
    self._affected_rows = self._read_query_result(unbuffered=unbuffered)
  File "/home/nilekrator/.local/lib/python3.7/site-packages/pymysql/connections.py", line 732, in _read_query_result
    result.read()
  File "/home/nilekrator/.local/lib/python3.7/site-packages/pymysql/connections.py", line 1075, in read
    first_packet = self.connection._read_packet()
  File "/home/nilekrator/.local/lib/python3.7/site-packages/pymysql/connections.py", line 684, in _read_packet
    packet.check_error()
  File "/home/nilekrator/.local/lib/python3.7/site-packages/pymysql/protocol.py", line 220, in check_error
    err.raise_mysql_exception(self._data)
  File "/home/nilekrator/.local/lib/python3.7/site-packages/pymysql/err.py", line 109, in raise_mysql_exception
    raise errorclass(errno, errval)
pymysql.err.ProgrammingError: (1146, "Table 'nilekrator$_2019.UG_ME_3' doesn't exist")
2020-01-05 20:43:50,869: Exception on /rank [GET]
Traceback (most recent call last):
  File "/usr/lib/python3.7/site-packages/flask/app.py", line 2292, in wsgi_app
    response = self.full_dispatch_request()
  File "/usr/lib/python3.7/site-packages/flask/app.py", line 1815, in full_dispatch_request
    rv = self.handle_user_exception(e)
  File "/usr/lib/python3.7/site-packages/flask_restful/__init__.py", line 273, in error_router
    return original_handler(e)
  File "/usr/lib/python3.7/site-packages/flask/app.py", line 1718, in handle_user_exception
    reraise(exc_type, exc_value, tb)
  File "/usr/lib/python3.7/site-packages/flask/_compat.py", line 35, in reraise
    raise value
  File "/usr/lib/python3.7/site-packages/flask/app.py", line 1813, in full_dispatch_request
    rv = self.dispatch_request()
  File "/usr/lib/python3.7/site-packages/flask/app.py", line 1799, in dispatch_request
    return self.view_functions[rule.endpoint](**req.view_args)
  File "/home/nilekrator/resultportal/extensions.py", line 12, in decorated_function
    return f(*args, **kwargs)
  File "/home/nilekrator/resultportal/student/student.py", line 219, in rank
    Stu.get_raw_rank()
  File "/home/nilekrator/resultportal/student/studentrank.py", line 39, in get_raw_rank
    method=self.method,
  File "/home/nilekrator/.local/lib/python3.7/site-packages/pymysql/cursors.py", line 170, in execute
    result = self._query(query)
  File "/home/nilekrator/.local/lib/python3.7/site-packages/pymysql/cursors.py", line 328, in _query
    conn.query(q)
  File "/home/nilekrator/.local/lib/python3.7/site-packages/pymysql/connections.py", line 517, in query
    self._affected_rows = self._read_query_result(unbuffered=unbuffered)
  File "/home/nilekrator/.local/lib/python3.7/site-packages/pymysql/connections.py", line 732, in _read_query_result
    result.read()
  File "/home/nilekrator/.local/lib/python3.7/site-packages/pymysql/connections.py", line 1075, in read
    first_packet = self.connection._read_packet()
  File "/home/nilekrator/.local/lib/python3.7/site-packages/pymysql/connections.py", line 684, in _read_packet
    packet.check_error()
  File "/home/nilekrator/.local/lib/python3.7/site-packages/pymysql/protocol.py", line 220, in check_error
    err.raise_mysql_exception(self._data)
  File "/home/nilekrator/.local/lib/python3.7/site-packages/pymysql/err.py", line 109, in raise_mysql_exception
    raise errorclass(errno, errval)
pymysql.err.ProgrammingError: (1146, "Table 'nilekrator$_2015.UG_ME_3' doesn't exist")
2020-01-05 20:48:50,690: OSError: write error
2020-01-06 03:33:28,954: OSError: write error
2020-01-06 03:33:30,091: OSError: write error
2020-01-06 04:26:40,271: OSError: write error
2020-01-06 04:59:25,899: Exception on /compare [POST]
Traceback (most recent call last):
  File "/usr/lib/python3.7/site-packages/flask/app.py", line 2292, in wsgi_app
    response = self.full_dispatch_request()
  File "/usr/lib/python3.7/site-packages/flask/app.py", line 1815, in full_dispatch_request
    rv = self.handle_user_exception(e)
  File "/usr/lib/python3.7/site-packages/flask_restful/__init__.py", line 273, in error_router
    return original_handler(e)
  File "/usr/lib/python3.7/site-packages/flask/app.py", line 1718, in handle_user_exception
    reraise(exc_type, exc_value, tb)
  File "/usr/lib/python3.7/site-packages/flask/_compat.py", line 35, in reraise
    raise value
  File "/usr/lib/python3.7/site-packages/flask/app.py", line 1813, in full_dispatch_request
    rv = self.dispatch_request()
  File "/usr/lib/python3.7/site-packages/flask/app.py", line 1799, in dispatch_request
    return self.view_functions[rule.endpoint](**req.view_args)
  File "/home/nilekrator/resultportal/extensions.py", line 12, in decorated_function
    return f(*args, **kwargs)
  File "/home/nilekrator/resultportal/student/student.py", line 141, in compare
    roll=session['roll']
  File "/home/nilekrator/.local/lib/python3.7/site-packages/pymysql/cursors.py", line 170, in execute
    result = self._query(query)
  File "/home/nilekrator/.local/lib/python3.7/site-packages/pymysql/cursors.py", line 328, in _query
    conn.query(q)
  File "/home/nilekrator/.local/lib/python3.7/site-packages/pymysql/connections.py", line 517, in query
    self._affected_rows = self._read_query_result(unbuffered=unbuffered)
  File "/home/nilekrator/.local/lib/python3.7/site-packages/pymysql/connections.py", line 732, in _read_query_result
    result.read()
  File "/home/nilekrator/.local/lib/python3.7/site-packages/pymysql/connections.py", line 1075, in read
    first_packet = self.connection._read_packet()
  File "/home/nilekrator/.local/lib/python3.7/site-packages/pymysql/connections.py", line 684, in _read_packet
    packet.check_error()
  File "/home/nilekrator/.local/lib/python3.7/site-packages/pymysql/protocol.py", line 220, in check_error
    err.raise_mysql_exception(self._data)
  File "/home/nilekrator/.local/lib/python3.7/site-packages/pymysql/err.py", line 109, in raise_mysql_exception
    raise errorclass(errno, errval)
pymysql.err.ProgrammingError: (1146, "Table 'nilekrator$_2018.PG_CACA_5' doesn't exist")
2020-01-06 06:10:17,809: Exception on /rank [GET]
Traceback (most recent call last):
  File "/usr/lib/python3.7/site-packages/flask/app.py", line 2292, in wsgi_app
    response = self.full_dispatch_request()
  File "/usr/lib/python3.7/site-packages/flask/app.py", line 1815, in full_dispatch_request
    rv = self.handle_user_exception(e)
  File "/usr/lib/python3.7/site-packages/flask_restful/__init__.py", line 273, in error_router
    return original_handler(e)
  File "/usr/lib/python3.7/site-packages/flask/app.py", line 1718, in handle_user_exception
    reraise(exc_type, exc_value, tb)
  File "/usr/lib/python3.7/site-packages/flask/_compat.py", line 35, in reraise
    raise value
  File "/usr/lib/python3.7/site-packages/flask/app.py", line 1813, in full_dispatch_request
    rv = self.dispatch_request()
  File "/usr/lib/python3.7/site-packages/flask/app.py", line 1799, in dispatch_request
    return self.view_functions[rule.endpoint](**req.view_args)
  File "/home/nilekrator/resultportal/extensions.py", line 12, in decorated_function
    return f(*args, **kwargs)
  File "/home/nilekrator/resultportal/student/student.py", line 219, in rank
    Stu.get_raw_rank()
  File "/home/nilekrator/resultportal/student/studentrank.py", line 39, in get_raw_rank
    method=self.method,
  File "/home/nilekrator/.local/lib/python3.7/site-packages/pymysql/cursors.py", line 170, in execute
    result = self._query(query)
  File "/home/nilekrator/.local/lib/python3.7/site-packages/pymysql/cursors.py", line 328, in _query
    conn.query(q)
  File "/home/nilekrator/.local/lib/python3.7/site-packages/pymysql/connections.py", line 517, in query
    self._affected_rows = self._read_query_result(unbuffered=unbuffered)
  File "/home/nilekrator/.local/lib/python3.7/site-packages/pymysql/connections.py", line 732, in _read_query_result
    result.read()
  File "/home/nilekrator/.local/lib/python3.7/site-packages/pymysql/connections.py", line 1075, in read
    first_packet = self.connection._read_packet()
  File "/home/nilekrator/.local/lib/python3.7/site-packages/pymysql/connections.py", line 684, in _read_packet
    packet.check_error()
  File "/home/nilekrator/.local/lib/python3.7/site-packages/pymysql/protocol.py", line 220, in check_error
    err.raise_mysql_exception(self._data)
  File "/home/nilekrator/.local/lib/python3.7/site-packages/pymysql/err.py", line 109, in raise_mysql_exception
    raise errorclass(errno, errval)
pymysql.err.ProgrammingError: (1146, "Table 'nilekrator$_2019.UG_ME_3' doesn't exist")
2020-01-06 06:10:19,767: Exception on /rank [GET]
Traceback (most recent call last):
  File "/usr/lib/python3.7/site-packages/flask/app.py", line 2292, in wsgi_app
    response = self.full_dispatch_request()
  File "/usr/lib/python3.7/site-packages/flask/app.py", line 1815, in full_dispatch_request
    rv = self.handle_user_exception(e)
  File "/usr/lib/python3.7/site-packages/flask_restful/__init__.py", line 273, in error_router
    return original_handler(e)
  File "/usr/lib/python3.7/site-packages/flask/app.py", line 1718, in handle_user_exception
    reraise(exc_type, exc_value, tb)
  File "/usr/lib/python3.7/site-packages/flask/_compat.py", line 35, in reraise
    raise value
  File "/usr/lib/python3.7/site-packages/flask/app.py", line 1813, in full_dispatch_request
    rv = self.dispatch_request()
  File "/usr/lib/python3.7/site-packages/flask/app.py", line 1799, in dispatch_request
    return self.view_functions[rule.endpoint](**req.view_args)
  File "/home/nilekrator/resultportal/extensions.py", line 12, in decorated_function
    return f(*args, **kwargs)
  File "/home/nilekrator/resultportal/student/student.py", line 219, in rank
    Stu.get_raw_rank()
  File "/home/nilekrator/resultportal/student/studentrank.py", line 39, in get_raw_rank
    method=self.method,
  File "/home/nilekrator/.local/lib/python3.7/site-packages/pymysql/cursors.py", line 170, in execute
    result = self._query(query)
  File "/home/nilekrator/.local/lib/python3.7/site-packages/pymysql/cursors.py", line 328, in _query
    conn.query(q)
  File "/home/nilekrator/.local/lib/python3.7/site-packages/pymysql/connections.py", line 517, in query
    self._affected_rows = self._read_query_result(unbuffered=unbuffered)
  File "/home/nilekrator/.local/lib/python3.7/site-packages/pymysql/connections.py", line 732, in _read_query_result
    result.read()
  File "/home/nilekrator/.local/lib/python3.7/site-packages/pymysql/connections.py", line 1075, in read
    first_packet = self.connection._read_packet()
  File "/home/nilekrator/.local/lib/python3.7/site-packages/pymysql/connections.py", line 684, in _read_packet
    packet.check_error()
  File "/home/nilekrator/.local/lib/python3.7/site-packages/pymysql/protocol.py", line 220, in check_error
    err.raise_mysql_exception(self._data)
  File "/home/nilekrator/.local/lib/python3.7/site-packages/pymysql/err.py", line 109, in raise_mysql_exception
    raise errorclass(errno, errval)
pymysql.err.ProgrammingError: (1146, "Table 'nilekrator$_2019.UG_ME_3' doesn't exist")
2020-01-06 06:10:21,582: Exception on /rank [GET]
Traceback (most recent call last):
  File "/usr/lib/python3.7/site-packages/flask/app.py", line 2292, in wsgi_app
    response = self.full_dispatch_request()
  File "/usr/lib/python3.7/site-packages/flask/app.py", line 1815, in full_dispatch_request
    rv = self.handle_user_exception(e)
  File "/usr/lib/python3.7/site-packages/flask_restful/__init__.py", line 273, in error_router
    return original_handler(e)
  File "/usr/lib/python3.7/site-packages/flask/app.py", line 1718, in handle_user_exception
    reraise(exc_type, exc_value, tb)
  File "/usr/lib/python3.7/site-packages/flask/_compat.py", line 35, in reraise
    raise value
  File "/usr/lib/python3.7/site-packages/flask/app.py", line 1813, in full_dispatch_request
    rv = self.dispatch_request()
  File "/usr/lib/python3.7/site-packages/flask/app.py", line 1799, in dispatch_request
    return self.view_functions[rule.endpoint](**req.view_args)
  File "/home/nilekrator/resultportal/extensions.py", line 12, in decorated_function
    return f(*args, **kwargs)
  File "/home/nilekrator/resultportal/student/student.py", line 219, in rank
    Stu.get_raw_rank()
  File "/home/nilekrator/resultportal/student/studentrank.py", line 39, in get_raw_rank
    method=self.method,
  File "/home/nilekrator/.local/lib/python3.7/site-packages/pymysql/cursors.py", line 170, in execute
    result = self._query(query)
  File "/home/nilekrator/.local/lib/python3.7/site-packages/pymysql/cursors.py", line 328, in _query
    conn.query(q)
  File "/home/nilekrator/.local/lib/python3.7/site-packages/pymysql/connections.py", line 517, in query
    self._affected_rows = self._read_query_result(unbuffered=unbuffered)
  File "/home/nilekrator/.local/lib/python3.7/site-packages/pymysql/connections.py", line 732, in _read_query_result
    result.read()
  File "/home/nilekrator/.local/lib/python3.7/site-packages/pymysql/connections.py", line 1075, in read
    first_packet = self.connection._read_packet()
  File "/home/nilekrator/.local/lib/python3.7/site-packages/pymysql/connections.py", line 684, in _read_packet
    packet.check_error()
  File "/home/nilekrator/.local/lib/python3.7/site-packages/pymysql/protocol.py", line 220, in check_error
    err.raise_mysql_exception(self._data)
  File "/home/nilekrator/.local/lib/python3.7/site-packages/pymysql/err.py", line 109, in raise_mysql_exception
    raise errorclass(errno, errval)
pymysql.err.ProgrammingError: (1146, "Table 'nilekrator$_2019.UG_ME_3' doesn't exist")
2020-01-06 06:10:28,592: Exception on /rank [GET]
Traceback (most recent call last):
  File "/usr/lib/python3.7/site-packages/flask/app.py", line 2292, in wsgi_app
    response = self.full_dispatch_request()
  File "/usr/lib/python3.7/site-packages/flask/app.py", line 1815, in full_dispatch_request
    rv = self.handle_user_exception(e)
  File "/usr/lib/python3.7/site-packages/flask_restful/__init__.py", line 273, in error_router
    return original_handler(e)
  File "/usr/lib/python3.7/site-packages/flask/app.py", line 1718, in handle_user_exception
    reraise(exc_type, exc_value, tb)
  File "/usr/lib/python3.7/site-packages/flask/_compat.py", line 35, in reraise
    raise value
  File "/usr/lib/python3.7/site-packages/flask/app.py", line 1813, in full_dispatch_request
    rv = self.dispatch_request()
  File "/usr/lib/python3.7/site-packages/flask/app.py", line 1799, in dispatch_request
    return self.view_functions[rule.endpoint](**req.view_args)
  File "/home/nilekrator/resultportal/extensions.py", line 12, in decorated_function
    return f(*args, **kwargs)
  File "/home/nilekrator/resultportal/student/student.py", line 219, in rank
    Stu.get_raw_rank()
  File "/home/nilekrator/resultportal/student/studentrank.py", line 39, in get_raw_rank
    method=self.method,
  File "/home/nilekrator/.local/lib/python3.7/site-packages/pymysql/cursors.py", line 170, in execute
    result = self._query(query)
  File "/home/nilekrator/.local/lib/python3.7/site-packages/pymysql/cursors.py", line 328, in _query
    conn.query(q)
  File "/home/nilekrator/.local/lib/python3.7/site-packages/pymysql/connections.py", line 517, in query
    self._affected_rows = self._read_query_result(unbuffered=unbuffered)
  File "/home/nilekrator/.local/lib/python3.7/site-packages/pymysql/connections.py", line 732, in _read_query_result
    result.read()
  File "/home/nilekrator/.local/lib/python3.7/site-packages/pymysql/connections.py", line 1075, in read
    first_packet = self.connection._read_packet()
  File "/home/nilekrator/.local/lib/python3.7/site-packages/pymysql/connections.py", line 684, in _read_packet
    packet.check_error()
  File "/home/nilekrator/.local/lib/python3.7/site-packages/pymysql/protocol.py", line 220, in check_error
    err.raise_mysql_exception(self._data)
  File "/home/nilekrator/.local/lib/python3.7/site-packages/pymysql/err.py", line 109, in raise_mysql_exception
    raise errorclass(errno, errval)
pymysql.err.ProgrammingError: (1146, "Table 'nilekrator$_2019.UG_ME_3' doesn't exist")
2020-01-06 06:10:36,933: Exception on /rank [GET]
Traceback (most recent call last):
  File "/usr/lib/python3.7/site-packages/flask/app.py", line 2292, in wsgi_app
    response = self.full_dispatch_request()
  File "/usr/lib/python3.7/site-packages/flask/app.py", line 1815, in full_dispatch_request
    rv = self.handle_user_exception(e)
  File "/usr/lib/python3.7/site-packages/flask_restful/__init__.py", line 273, in error_router
    return original_handler(e)
  File "/usr/lib/python3.7/site-packages/flask/app.py", line 1718, in handle_user_exception
    reraise(exc_type, exc_value, tb)
  File "/usr/lib/python3.7/site-packages/flask/_compat.py", line 35, in reraise
    raise value
  File "/usr/lib/python3.7/site-packages/flask/app.py", line 1813, in full_dispatch_request
    rv = self.dispatch_request()
  File "/usr/lib/python3.7/site-packages/flask/app.py", line 1799, in dispatch_request
    return self.view_functions[rule.endpoint](**req.view_args)
  File "/home/nilekrator/resultportal/extensions.py", line 12, in decorated_function
    return f(*args, **kwargs)
  File "/home/nilekrator/resultportal/student/student.py", line 219, in rank
    Stu.get_raw_rank()
  File "/home/nilekrator/resultportal/student/studentrank.py", line 39, in get_raw_rank
    method=self.method,
  File "/home/nilekrator/.local/lib/python3.7/site-packages/pymysql/cursors.py", line 170, in execute
    result = self._query(query)
  File "/home/nilekrator/.local/lib/python3.7/site-packages/pymysql/cursors.py", line 328, in _query
    conn.query(q)
  File "/home/nilekrator/.local/lib/python3.7/site-packages/pymysql/connections.py", line 517, in query
    self._affected_rows = self._read_query_result(unbuffered=unbuffered)
  File "/home/nilekrator/.local/lib/python3.7/site-packages/pymysql/connections.py", line 732, in _read_query_result
    result.read()
  File "/home/nilekrator/.local/lib/python3.7/site-packages/pymysql/connections.py", line 1075, in read
    first_packet = self.connection._read_packet()
  File "/home/nilekrator/.local/lib/python3.7/site-packages/pymysql/connections.py", line 684, in _read_packet
    packet.check_error()
  File "/home/nilekrator/.local/lib/python3.7/site-packages/pymysql/protocol.py", line 220, in check_error
    err.raise_mysql_exception(self._data)
  File "/home/nilekrator/.local/lib/python3.7/site-packages/pymysql/err.py", line 109, in raise_mysql_exception
    raise errorclass(errno, errval)
pymysql.err.ProgrammingError: (1146, "Table 'nilekrator$_2019.UG_ME_3' doesn't exist")
2020-01-06 06:10:43,288: Exception on /rank [GET]
Traceback (most recent call last):
  File "/usr/lib/python3.7/site-packages/flask/app.py", line 2292, in wsgi_app
    response = self.full_dispatch_request()
  File "/usr/lib/python3.7/site-packages/flask/app.py", line 1815, in full_dispatch_request
    rv = self.handle_user_exception(e)
  File "/usr/lib/python3.7/site-packages/flask_restful/__init__.py", line 273, in error_router
    return original_handler(e)
  File "/usr/lib/python3.7/site-packages/flask/app.py", line 1718, in handle_user_exception
    reraise(exc_type, exc_value, tb)
  File "/usr/lib/python3.7/site-packages/flask/_compat.py", line 35, in reraise
    raise value
  File "/usr/lib/python3.7/site-packages/flask/app.py", line 1813, in full_dispatch_request
    rv = self.dispatch_request()
  File "/usr/lib/python3.7/site-packages/flask/app.py", line 1799, in dispatch_request
    return self.view_functions[rule.endpoint](**req.view_args)
  File "/home/nilekrator/resultportal/extensions.py", line 12, in decorated_function
    return f(*args, **kwargs)
  File "/home/nilekrator/resultportal/student/student.py", line 219, in rank
    Stu.get_raw_rank()
  File "/home/nilekrator/resultportal/student/studentrank.py", line 39, in get_raw_rank
    method=self.method,
  File "/home/nilekrator/.local/lib/python3.7/site-packages/pymysql/cursors.py", line 170, in execute
    result = self._query(query)
  File "/home/nilekrator/.local/lib/python3.7/site-packages/pymysql/cursors.py", line 328, in _query
    conn.query(q)
  File "/home/nilekrator/.local/lib/python3.7/site-packages/pymysql/connections.py", line 517, in query
    self._affected_rows = self._read_query_result(unbuffered=unbuffered)
  File "/home/nilekrator/.local/lib/python3.7/site-packages/pymysql/connections.py", line 732, in _read_query_result
    result.read()
  File "/home/nilekrator/.local/lib/python3.7/site-packages/pymysql/connections.py", line 1075, in read
    first_packet = self.connection._read_packet()
  File "/home/nilekrator/.local/lib/python3.7/site-packages/pymysql/connections.py", line 684, in _read_packet
    packet.check_error()
  File "/home/nilekrator/.local/lib/python3.7/site-packages/pymysql/protocol.py", line 220, in check_error
    err.raise_mysql_exception(self._data)
  File "/home/nilekrator/.local/lib/python3.7/site-packages/pymysql/err.py", line 109, in raise_mysql_exception
    raise errorclass(errno, errval)
pymysql.err.ProgrammingError: (1146, "Table 'nilekrator$_2019.UG_ME_3' doesn't exist")
2020-01-06 06:25:14,166: OSError: write error
2020-01-06 06:50:20,669: Exception on /rank [GET]
Traceback (most recent call last):
  File "/usr/lib/python3.7/site-packages/flask/app.py", line 2292, in wsgi_app
    response = self.full_dispatch_request()
  File "/usr/lib/python3.7/site-packages/flask/app.py", line 1815, in full_dispatch_request
    rv = self.handle_user_exception(e)
  File "/usr/lib/python3.7/site-packages/flask_restful/__init__.py", line 273, in error_router
    return original_handler(e)
  File "/usr/lib/python3.7/site-packages/flask/app.py", line 1718, in handle_user_exception
    reraise(exc_type, exc_value, tb)
  File "/usr/lib/python3.7/site-packages/flask/_compat.py", line 35, in reraise
    raise value
  File "/usr/lib/python3.7/site-packages/flask/app.py", line 1813, in full_dispatch_request
    rv = self.dispatch_request()
  File "/usr/lib/python3.7/site-packages/flask/app.py", line 1799, in dispatch_request
    return self.view_functions[rule.endpoint](**req.view_args)
  File "/home/nilekrator/resultportal/extensions.py", line 12, in decorated_function
    return f(*args, **kwargs)
  File "/home/nilekrator/resultportal/student/student.py", line 219, in rank
    Stu.get_raw_rank()
  File "/home/nilekrator/resultportal/student/studentrank.py", line 39, in get_raw_rank
    method=self.method,
  File "/home/nilekrator/.local/lib/python3.7/site-packages/pymysql/cursors.py", line 170, in execute
    result = self._query(query)
  File "/home/nilekrator/.local/lib/python3.7/site-packages/pymysql/cursors.py", line 328, in _query
    conn.query(q)
  File "/home/nilekrator/.local/lib/python3.7/site-packages/pymysql/connections.py", line 517, in query
    self._affected_rows = self._read_query_result(unbuffered=unbuffered)
  File "/home/nilekrator/.local/lib/python3.7/site-packages/pymysql/connections.py", line 732, in _read_query_result
    result.read()
  File "/home/nilekrator/.local/lib/python3.7/site-packages/pymysql/connections.py", line 1075, in read
    first_packet = self.connection._read_packet()
  File "/home/nilekrator/.local/lib/python3.7/site-packages/pymysql/connections.py", line 684, in _read_packet
    packet.check_error()
  File "/home/nilekrator/.local/lib/python3.7/site-packages/pymysql/protocol.py", line 220, in check_error
    err.raise_mysql_exception(self._data)
  File "/home/nilekrator/.local/lib/python3.7/site-packages/pymysql/err.py", line 109, in raise_mysql_exception
    raise errorclass(errno, errval)
pymysql.err.ProgrammingError: (1146, "Table 'nilekrator$_2018.UG_PI_5' doesn't exist")
2020-01-06 07:08:45,851: OSError: write error
2020-01-06 07:12:08,369: OSError: write error
2020-01-06 07:12:08,558: OSError: write error
2020-01-06 07:13:16,625: OSError: write error
2020-01-06 07:13:17,145: OSError: write error
2020-01-06 07:42:28,282: OSError: write error
2020-01-06 07:56:38,946: OSError: write error
2020-01-06 08:11:24,641: OSError: write error
2020-01-06 08:31:31,265: OSError: write error
2020-01-06 08:51:18,202: OSError: write error
2020-01-06 08:56:25,403: OSError: write error
2020-01-06 08:56:27,184: OSError: write error
2020-01-06 08:56:28,994: OSError: write error
2020-01-06 08:56:32,254: OSError: write error
2020-01-06 08:56:32,697: OSError: write error
2020-01-06 08:56:34,572: OSError: write error
2020-01-06 09:00:28,633: OSError: write error
2020-01-06 10:03:31,901: OSError: write error
2020-01-06 10:03:34,716: OSError: write error
2020-01-06 10:03:37,423: OSError: write error
2020-01-06 12:12:23,610: OSError: write error
2020-01-06 13:27:59,992: OSError: write error
2020-01-06 13:28:00,456: OSError: write error
2020-01-06 13:28:00,491: OSError: write error
2020-01-06 13:31:23,027: Exception on /student/2017UGCS036 [GET]
Traceback (most recent call last):
  File "/usr/lib/python3.7/urllib/request.py", line 1317, in do_open
    encode_chunked=req.has_header('Transfer-encoding'))
  File "/usr/lib/python3.7/http/client.py", line 1229, in request
    self._send_request(method, url, body, headers, encode_chunked)
  File "/usr/lib/python3.7/http/client.py", line 1275, in _send_request
    self.endheaders(body, encode_chunked=encode_chunked)
  File "/usr/lib/python3.7/http/client.py", line 1224, in endheaders
    self._send_output(message_body, encode_chunked=encode_chunked)
  File "/usr/lib/python3.7/http/client.py", line 1016, in _send_output
    self.send(msg)
  File "/usr/lib/python3.7/http/client.py", line 956, in send
    self.connect()
  File "/usr/lib/python3.7/http/client.py", line 928, in connect
    (self.host,self.port), self.timeout, self.source_address)
  File "/usr/lib/python3.7/socket.py", line 727, in create_connection
    raise err
  File "/usr/lib/python3.7/socket.py", line 716, in create_connection
    sock.connect(sa)
TimeoutError: [Errno 110] Connection timed out
**NO MATCH**
During handling of the above exception, another exception occurred:
**NO MATCH**
Traceback (most recent call last):
  File "/usr/lib/python3.7/site-packages/flask/app.py", line 1813, in full_dispatch_request
    rv = self.dispatch_request()
  File "/usr/lib/python3.7/site-packages/flask/app.py", line 1799, in dispatch_request
    return self.view_functions[rule.endpoint](**req.view_args)
  File "/usr/lib/python3.7/site-packages/flask_restful/__init__.py", line 480, in wrapper
    resp = resource(*args, **kwargs)
  File "/usr/lib/python3.7/site-packages/flask/views.py", line 88, in view
    return self.dispatch_request(*args, **kwargs)
  File "/usr/lib/python3.7/site-packages/flask_restful/__init__.py", line 595, in dispatch_request
    resp = meth(*args, **kwargs)
  File "/home/nilekrator/resultportal/scraper/student_api.py", line 37, in get
    semesters, next_request_post_data, status_code = STUDENT.first_call_response()
  File "/home/nilekrator/resultportal/scraper/student_api.py", line 213, in first_call_response
    req = request.urlopen(self.url, parse.urlencode(post_data).encode('utf-8'))
  File "/usr/lib/python3.7/urllib/request.py", line 222, in urlopen
    return opener.open(url, data, timeout)
  File "/usr/lib/python3.7/urllib/request.py", line 525, in open
    response = self._open(req, data)
  File "/usr/lib/python3.7/urllib/request.py", line 543, in _open
    '_open', req)
  File "/usr/lib/python3.7/urllib/request.py", line 503, in _call_chain
    result = func(*args)
  File "/usr/lib/python3.7/urllib/request.py", line 1345, in http_open
    return self.do_open(http.client.HTTPConnection, req)
  File "/usr/lib/python3.7/urllib/request.py", line 1319, in do_open
    raise URLError(err)
urllib.error.URLError: <urlopen error [Errno 110] Connection timed out>
2020-01-06 13:50:50,826: OSError: write error
2020-01-06 15:02:34,236: OSError: write error
2020-01-06 15:02:35,171: OSError: write error
2020-01-06 15:02:36,231: OSError: write error
2020-01-06 15:02:38,407: OSError: write error
2020-01-06 15:02:39,168: OSError: write error
2020-01-06 15:09:54,689: OSError: write error
2020-01-06 15:09:54,887: OSError: write error
2020-01-06 15:09:55,305: OSError: write error
2020-01-06 15:15:20,587: OSError: write error
2020-01-06 15:15:47,955: OSError: write error
2020-01-06 15:15:49,969: OSError: write error
2020-01-06 15:15:51,825: OSError: write error
2020-01-06 15:15:53,740: OSError: write error
2020-01-06 15:15:54,194: OSError: write error
2020-01-06 15:15:55,328: OSError: write error
2020-01-06 15:15:56,510: OSError: write error
2020-01-06 15:15:58,358: OSError: write error
2020-01-06 15:45:08,132: OSError: write error
2020-01-06 16:22:30,912: OSError: write error
2020-01-06 16:22:32,787: OSError: write error
2020-01-06 17:09:28,173: OSError: write error
2020-01-06 17:16:23,676: OSError: write error
2020-01-06 18:02:39,169: OSError: write error
2020-01-06 18:04:52,406: OSError: write error
2020-01-06 18:09:39,103: OSError: write error
2020-01-06 18:09:39,610: OSError: write error
2020-01-06 18:09:40,567: OSError: write error
2020-01-07 01:43:55,141: OSError: write error
2020-01-07 01:48:23,719: Retrying (Retry(total=2, connect=None, read=None, redirect=None, status=None)) after connection broken by 'SSLError(SSLEOFError(8, 'EOF occurred in violation of protocol (_ssl.c:1045)'))': /api/1471638/store/
2020-01-07 02:36:51,386: OSError: write error
2020-01-07 02:36:54,133: OSError: write error
2020-01-07 02:36:55,486: OSError: write error
2020-01-07 02:37:20,173: OSError: write error
2020-01-07 02:42:33,208: OSError: write error
2020-01-07 02:52:10,561: OSError: write error
2020-01-07 03:18:26,432: OSError: write error
2020-01-07 04:31:46,947: OSError: write error
2020-01-07 04:59:03,400: OSError: write error
2020-01-07 05:44:35,718: OSError: write error
2020-01-07 06:45:18,401: OSError: write error
2020-01-07 06:45:53,982: OSError: write error
2020-01-07 07:41:01,315: OSError: write error
2020-01-07 08:31:47,431: OSError: write error
2020-01-07 08:33:32,777: OSError: write error
2020-01-07 08:33:34,712: OSError: write error
2020-01-07 09:02:43,717: OSError: write error
2020-01-07 09:02:43,749: OSError: write error
2020-01-07 09:02:46,483: OSError: write error
2020-01-07 09:02:48,625: OSError: write error
2020-01-07 09:02:50,177: OSError: write error
2020-01-07 09:57:26,288: OSError: write error
2020-01-07 10:38:39,202: OSError: write error
2020-01-07 11:05:21,653: OSError: write error
2020-01-07 13:25:21,354: OSError: write error
2020-01-07 13:29:32,492: OSError: write error
2020-01-07 13:29:32,536: OSError: write error
2020-01-07 13:29:32,642: OSError: write error
2020-01-07 13:29:32,668: OSError: write error
2020-01-07 13:29:32,743: OSError: write error
2020-01-07 13:29:32,751: OSError: write error
2020-01-07 13:29:32,853: OSError: write error
2020-01-07 13:29:32,880: OSError: write error
2020-01-07 13:29:32,963: OSError: write error
2020-01-07 13:29:32,973: OSError: write error
2020-01-07 13:29:33,041: OSError: write error
2020-01-07 13:53:21,784: OSError: write error
2020-01-07 13:53:21,929: OSError: write error
2020-01-07 13:53:24,133: OSError: write error
2020-01-07 13:53:24,563: OSError: write error
2020-01-07 13:59:54,636: OSError: write error
2020-01-07 14:00:49,519: OSError: write error
2020-01-07 15:18:51,942: Exception on /rank [GET]
Traceback (most recent call last):
  File "/usr/lib/python3.7/site-packages/flask/app.py", line 2292, in wsgi_app
    response = self.full_dispatch_request()
  File "/usr/lib/python3.7/site-packages/flask/app.py", line 1815, in full_dispatch_request
    rv = self.handle_user_exception(e)
  File "/usr/lib/python3.7/site-packages/flask_restful/__init__.py", line 273, in error_router
    return original_handler(e)
  File "/usr/lib/python3.7/site-packages/flask/app.py", line 1718, in handle_user_exception
    reraise(exc_type, exc_value, tb)
  File "/usr/lib/python3.7/site-packages/flask/_compat.py", line 35, in reraise
    raise value
  File "/usr/lib/python3.7/site-packages/flask/app.py", line 1813, in full_dispatch_request
    rv = self.dispatch_request()
  File "/usr/lib/python3.7/site-packages/flask/app.py", line 1799, in dispatch_request
    return self.view_functions[rule.endpoint](**req.view_args)
  File "/home/nilekrator/resultportal/extensions.py", line 12, in decorated_function
    return f(*args, **kwargs)
  File "/home/nilekrator/resultportal/student/student.py", line 219, in rank
    Stu.get_raw_rank()
  File "/home/nilekrator/resultportal/student/studentrank.py", line 39, in get_raw_rank
    method=self.method,
  File "/home/nilekrator/.local/lib/python3.7/site-packages/pymysql/cursors.py", line 170, in execute
    result = self._query(query)
  File "/home/nilekrator/.local/lib/python3.7/site-packages/pymysql/cursors.py", line 328, in _query
    conn.query(q)
  File "/home/nilekrator/.local/lib/python3.7/site-packages/pymysql/connections.py", line 517, in query
    self._affected_rows = self._read_query_result(unbuffered=unbuffered)
  File "/home/nilekrator/.local/lib/python3.7/site-packages/pymysql/connections.py", line 732, in _read_query_result
    result.read()
  File "/home/nilekrator/.local/lib/python3.7/site-packages/pymysql/connections.py", line 1075, in read
    first_packet = self.connection._read_packet()
  File "/home/nilekrator/.local/lib/python3.7/site-packages/pymysql/connections.py", line 684, in _read_packet
    packet.check_error()
  File "/home/nilekrator/.local/lib/python3.7/site-packages/pymysql/protocol.py", line 220, in check_error
    err.raise_mysql_exception(self._data)
  File "/home/nilekrator/.local/lib/python3.7/site-packages/pymysql/err.py", line 109, in raise_mysql_exception
    raise errorclass(errno, errval)
pymysql.err.ProgrammingError: (1146, "Table 'nilekrator$_2019.UG_MM_5' doesn't exist")
2020-01-07 15:19:08,388: Exception on /rank [GET]
Traceback (most recent call last):
  File "/usr/lib/python3.7/site-packages/flask/app.py", line 2292, in wsgi_app
    response = self.full_dispatch_request()
  File "/usr/lib/python3.7/site-packages/flask/app.py", line 1815, in full_dispatch_request
    rv = self.handle_user_exception(e)
  File "/usr/lib/python3.7/site-packages/flask_restful/__init__.py", line 273, in error_router
    return original_handler(e)
  File "/usr/lib/python3.7/site-packages/flask/app.py", line 1718, in handle_user_exception
    reraise(exc_type, exc_value, tb)
  File "/usr/lib/python3.7/site-packages/flask/_compat.py", line 35, in reraise
    raise value
  File "/usr/lib/python3.7/site-packages/flask/app.py", line 1813, in full_dispatch_request
    rv = self.dispatch_request()
  File "/usr/lib/python3.7/site-packages/flask/app.py", line 1799, in dispatch_request
    return self.view_functions[rule.endpoint](**req.view_args)
  File "/home/nilekrator/resultportal/extensions.py", line 12, in decorated_function
    return f(*args, **kwargs)
  File "/home/nilekrator/resultportal/student/student.py", line 219, in rank
    Stu.get_raw_rank()
  File "/home/nilekrator/resultportal/student/studentrank.py", line 39, in get_raw_rank
    method=self.method,
  File "/home/nilekrator/.local/lib/python3.7/site-packages/pymysql/cursors.py", line 170, in execute
    result = self._query(query)
  File "/home/nilekrator/.local/lib/python3.7/site-packages/pymysql/cursors.py", line 328, in _query
    conn.query(q)
  File "/home/nilekrator/.local/lib/python3.7/site-packages/pymysql/connections.py", line 517, in query
    self._affected_rows = self._read_query_result(unbuffered=unbuffered)
  File "/home/nilekrator/.local/lib/python3.7/site-packages/pymysql/connections.py", line 732, in _read_query_result
    result.read()
  File "/home/nilekrator/.local/lib/python3.7/site-packages/pymysql/connections.py", line 1075, in read
    first_packet = self.connection._read_packet()
  File "/home/nilekrator/.local/lib/python3.7/site-packages/pymysql/connections.py", line 684, in _read_packet
    packet.check_error()
  File "/home/nilekrator/.local/lib/python3.7/site-packages/pymysql/protocol.py", line 220, in check_error
    err.raise_mysql_exception(self._data)
  File "/home/nilekrator/.local/lib/python3.7/site-packages/pymysql/err.py", line 109, in raise_mysql_exception
    raise errorclass(errno, errval)
pymysql.err.ProgrammingError: (1146, "Table 'nilekrator$_2019.UG_MM_5' doesn't exist")
2020-01-07 15:19:44,978: Exception on /rank [GET]
Traceback (most recent call last):
  File "/usr/lib/python3.7/site-packages/flask/app.py", line 2292, in wsgi_app
    response = self.full_dispatch_request()
  File "/usr/lib/python3.7/site-packages/flask/app.py", line 1815, in full_dispatch_request
    rv = self.handle_user_exception(e)
  File "/usr/lib/python3.7/site-packages/flask_restful/__init__.py", line 273, in error_router
    return original_handler(e)
  File "/usr/lib/python3.7/site-packages/flask/app.py", line 1718, in handle_user_exception
    reraise(exc_type, exc_value, tb)
  File "/usr/lib/python3.7/site-packages/flask/_compat.py", line 35, in reraise
    raise value
  File "/usr/lib/python3.7/site-packages/flask/app.py", line 1813, in full_dispatch_request
    rv = self.dispatch_request()
  File "/usr/lib/python3.7/site-packages/flask/app.py", line 1799, in dispatch_request
    return self.view_functions[rule.endpoint](**req.view_args)
  File "/home/nilekrator/resultportal/extensions.py", line 12, in decorated_function
    return f(*args, **kwargs)
  File "/home/nilekrator/resultportal/student/student.py", line 219, in rank
    Stu.get_raw_rank()
  File "/home/nilekrator/resultportal/student/studentrank.py", line 39, in get_raw_rank
    method=self.method,
  File "/home/nilekrator/.local/lib/python3.7/site-packages/pymysql/cursors.py", line 170, in execute
    result = self._query(query)
  File "/home/nilekrator/.local/lib/python3.7/site-packages/pymysql/cursors.py", line 328, in _query
    conn.query(q)
  File "/home/nilekrator/.local/lib/python3.7/site-packages/pymysql/connections.py", line 517, in query
    self._affected_rows = self._read_query_result(unbuffered=unbuffered)
  File "/home/nilekrator/.local/lib/python3.7/site-packages/pymysql/connections.py", line 732, in _read_query_result
    result.read()
  File "/home/nilekrator/.local/lib/python3.7/site-packages/pymysql/connections.py", line 1075, in read
    first_packet = self.connection._read_packet()
  File "/home/nilekrator/.local/lib/python3.7/site-packages/pymysql/connections.py", line 684, in _read_packet
    packet.check_error()
  File "/home/nilekrator/.local/lib/python3.7/site-packages/pymysql/protocol.py", line 220, in check_error
    err.raise_mysql_exception(self._data)
  File "/home/nilekrator/.local/lib/python3.7/site-packages/pymysql/err.py", line 109, in raise_mysql_exception
    raise errorclass(errno, errval)
pymysql.err.ProgrammingError: (1146, "Table 'nilekrator$_2019.UG_MM_5' doesn't exist")
2020-01-07 15:32:25,905: OSError: write error
2020-01-07 15:42:10,540: Exception on /rank [GET]
Traceback (most recent call last):
  File "/usr/lib/python3.7/site-packages/flask/app.py", line 2292, in wsgi_app
    response = self.full_dispatch_request()
  File "/usr/lib/python3.7/site-packages/flask/app.py", line 1815, in full_dispatch_request
    rv = self.handle_user_exception(e)
  File "/usr/lib/python3.7/site-packages/flask_restful/__init__.py", line 273, in error_router
    return original_handler(e)
  File "/usr/lib/python3.7/site-packages/flask/app.py", line 1718, in handle_user_exception
    reraise(exc_type, exc_value, tb)
  File "/usr/lib/python3.7/site-packages/flask/_compat.py", line 35, in reraise
    raise value
  File "/usr/lib/python3.7/site-packages/flask/app.py", line 1813, in full_dispatch_request
    rv = self.dispatch_request()
  File "/usr/lib/python3.7/site-packages/flask/app.py", line 1799, in dispatch_request
    return self.view_functions[rule.endpoint](**req.view_args)
  File "/home/nilekrator/resultportal/extensions.py", line 12, in decorated_function
    return f(*args, **kwargs)
  File "/home/nilekrator/resultportal/student/student.py", line 219, in rank
    Stu.get_raw_rank()
  File "/home/nilekrator/resultportal/student/studentrank.py", line 39, in get_raw_rank
    method=self.method,
  File "/home/nilekrator/.local/lib/python3.7/site-packages/pymysql/cursors.py", line 170, in execute
    result = self._query(query)
  File "/home/nilekrator/.local/lib/python3.7/site-packages/pymysql/cursors.py", line 328, in _query
    conn.query(q)
  File "/home/nilekrator/.local/lib/python3.7/site-packages/pymysql/connections.py", line 517, in query
    self._affected_rows = self._read_query_result(unbuffered=unbuffered)
  File "/home/nilekrator/.local/lib/python3.7/site-packages/pymysql/connections.py", line 732, in _read_query_result
    result.read()
  File "/home/nilekrator/.local/lib/python3.7/site-packages/pymysql/connections.py", line 1075, in read
    first_packet = self.connection._read_packet()
  File "/home/nilekrator/.local/lib/python3.7/site-packages/pymysql/connections.py", line 684, in _read_packet
    packet.check_error()
  File "/home/nilekrator/.local/lib/python3.7/site-packages/pymysql/protocol.py", line 220, in check_error
    err.raise_mysql_exception(self._data)
  File "/home/nilekrator/.local/lib/python3.7/site-packages/pymysql/err.py", line 109, in raise_mysql_exception
    raise errorclass(errno, errval)
pymysql.err.ProgrammingError: (1146, "Table 'nilekrator$_2019.UG_MM_5' doesn't exist")
2020-01-07 15:48:36,985: Exception on /rank [GET]
Traceback (most recent call last):
  File "/usr/lib/python3.7/site-packages/flask/app.py", line 2292, in wsgi_app
    response = self.full_dispatch_request()
  File "/usr/lib/python3.7/site-packages/flask/app.py", line 1815, in full_dispatch_request
    rv = self.handle_user_exception(e)
  File "/usr/lib/python3.7/site-packages/flask_restful/__init__.py", line 273, in error_router
    return original_handler(e)
  File "/usr/lib/python3.7/site-packages/flask/app.py", line 1718, in handle_user_exception
    reraise(exc_type, exc_value, tb)
  File "/usr/lib/python3.7/site-packages/flask/_compat.py", line 35, in reraise
    raise value
  File "/usr/lib/python3.7/site-packages/flask/app.py", line 1813, in full_dispatch_request
    rv = self.dispatch_request()
  File "/usr/lib/python3.7/site-packages/flask/app.py", line 1799, in dispatch_request
    return self.view_functions[rule.endpoint](**req.view_args)
  File "/home/nilekrator/resultportal/extensions.py", line 12, in decorated_function
    return f(*args, **kwargs)
  File "/home/nilekrator/resultportal/student/student.py", line 219, in rank
    Stu.get_raw_rank()
  File "/home/nilekrator/resultportal/student/studentrank.py", line 39, in get_raw_rank
    method=self.method,
  File "/home/nilekrator/.local/lib/python3.7/site-packages/pymysql/cursors.py", line 170, in execute
    result = self._query(query)
  File "/home/nilekrator/.local/lib/python3.7/site-packages/pymysql/cursors.py", line 328, in _query
    conn.query(q)
  File "/home/nilekrator/.local/lib/python3.7/site-packages/pymysql/connections.py", line 517, in query
    self._affected_rows = self._read_query_result(unbuffered=unbuffered)
  File "/home/nilekrator/.local/lib/python3.7/site-packages/pymysql/connections.py", line 732, in _read_query_result
    result.read()
  File "/home/nilekrator/.local/lib/python3.7/site-packages/pymysql/connections.py", line 1075, in read
    first_packet = self.connection._read_packet()
  File "/home/nilekrator/.local/lib/python3.7/site-packages/pymysql/connections.py", line 684, in _read_packet
    packet.check_error()
  File "/home/nilekrator/.local/lib/python3.7/site-packages/pymysql/protocol.py", line 220, in check_error
    err.raise_mysql_exception(self._data)
  File "/home/nilekrator/.local/lib/python3.7/site-packages/pymysql/err.py", line 109, in raise_mysql_exception
    raise errorclass(errno, errval)
pymysql.err.ProgrammingError: (1146, "Table 'nilekrator$_2019.UG_MM_5' doesn't exist")
2020-01-07 15:49:08,805: Exception on /rank [GET]
Traceback (most recent call last):
  File "/usr/lib/python3.7/site-packages/flask/app.py", line 2292, in wsgi_app
    response = self.full_dispatch_request()
  File "/usr/lib/python3.7/site-packages/flask/app.py", line 1815, in full_dispatch_request
    rv = self.handle_user_exception(e)
  File "/usr/lib/python3.7/site-packages/flask_restful/__init__.py", line 273, in error_router
    return original_handler(e)
  File "/usr/lib/python3.7/site-packages/flask/app.py", line 1718, in handle_user_exception
    reraise(exc_type, exc_value, tb)
  File "/usr/lib/python3.7/site-packages/flask/_compat.py", line 35, in reraise
    raise value
  File "/usr/lib/python3.7/site-packages/flask/app.py", line 1813, in full_dispatch_request
    rv = self.dispatch_request()
  File "/usr/lib/python3.7/site-packages/flask/app.py", line 1799, in dispatch_request
    return self.view_functions[rule.endpoint](**req.view_args)
  File "/home/nilekrator/resultportal/extensions.py", line 12, in decorated_function
    return f(*args, **kwargs)
  File "/home/nilekrator/resultportal/student/student.py", line 219, in rank
    Stu.get_raw_rank()
  File "/home/nilekrator/resultportal/student/studentrank.py", line 39, in get_raw_rank
    method=self.method,
  File "/home/nilekrator/.local/lib/python3.7/site-packages/pymysql/cursors.py", line 170, in execute
    result = self._query(query)
  File "/home/nilekrator/.local/lib/python3.7/site-packages/pymysql/cursors.py", line 328, in _query
    conn.query(q)
  File "/home/nilekrator/.local/lib/python3.7/site-packages/pymysql/connections.py", line 517, in query
    self._affected_rows = self._read_query_result(unbuffered=unbuffered)
  File "/home/nilekrator/.local/lib/python3.7/site-packages/pymysql/connections.py", line 732, in _read_query_result
    result.read()
  File "/home/nilekrator/.local/lib/python3.7/site-packages/pymysql/connections.py", line 1075, in read
    first_packet = self.connection._read_packet()
  File "/home/nilekrator/.local/lib/python3.7/site-packages/pymysql/connections.py", line 684, in _read_packet
    packet.check_error()
  File "/home/nilekrator/.local/lib/python3.7/site-packages/pymysql/protocol.py", line 220, in check_error
    err.raise_mysql_exception(self._data)
  File "/home/nilekrator/.local/lib/python3.7/site-packages/pymysql/err.py", line 109, in raise_mysql_exception
    raise errorclass(errno, errval)
pymysql.err.ProgrammingError: (1146, "Table 'nilekrator$_2019.UG_MM_5' doesn't exist")
2020-01-07 16:00:23,593: OSError: write error
2020-01-07 16:59:58,785: OSError: write error
2020-01-07 16:59:59,417: OSError: write error
2020-01-07 17:47:59,138: OSError: write error
2020-01-07 17:58:25,369: OSError: write error
2020-01-07 18:01:19,250: OSError: write error
2020-01-07 18:34:42,617: OSError: write error
2020-01-08 04:33:33,565: OSError: write error
2020-01-08 04:41:54,165: OSError: write error
2020-01-08 04:41:56,992: OSError: write error
2020-01-08 04:41:57,219: OSError: write error
2020-01-08 05:17:17,303: OSError: write error
2020-01-08 06:32:58,838: OSError: write error
2020-01-08 06:33:00,359: OSError: write error
2020-01-08 06:44:27,820: OSError: write error
2020-01-08 07:17:14,435: OSError: write error
2020-01-08 07:25:46,599: OSError: write error
2020-01-08 07:34:44,247: OSError: write error
2020-01-08 08:13:40,568: OSError: write error
2020-01-08 08:17:01,873: OSError: write error
2020-01-08 08:17:15,519: OSError: write error
2020-01-08 08:17:18,141: OSError: write error
2020-01-08 08:34:20,120: OSError: write error
2020-01-08 08:40:25,007: OSError: write error
2020-01-08 08:40:25,277: OSError: write error
2020-01-08 09:53:00,741: OSError: write error
2020-01-08 09:53:00,817: OSError: write error
2020-01-08 10:12:42,399: OSError: write error
2020-01-08 11:19:48,361: OSError: write error
2020-01-08 12:12:31,707: Exception on /rank [GET]
Traceback (most recent call last):
  File "/usr/lib/python3.7/site-packages/flask/app.py", line 2292, in wsgi_app
    response = self.full_dispatch_request()
  File "/usr/lib/python3.7/site-packages/flask/app.py", line 1815, in full_dispatch_request
    rv = self.handle_user_exception(e)
  File "/usr/lib/python3.7/site-packages/flask_restful/__init__.py", line 273, in error_router
    return original_handler(e)
  File "/usr/lib/python3.7/site-packages/flask/app.py", line 1718, in handle_user_exception
    reraise(exc_type, exc_value, tb)
  File "/usr/lib/python3.7/site-packages/flask/_compat.py", line 35, in reraise
    raise value
  File "/usr/lib/python3.7/site-packages/flask/app.py", line 1813, in full_dispatch_request
    rv = self.dispatch_request()
  File "/usr/lib/python3.7/site-packages/flask/app.py", line 1799, in dispatch_request
    return self.view_functions[rule.endpoint](**req.view_args)
  File "/home/nilekrator/resultportal/extensions.py", line 12, in decorated_function
    return f(*args, **kwargs)
  File "/home/nilekrator/resultportal/student/student.py", line 219, in rank
    Stu.get_raw_rank()
  File "/home/nilekrator/resultportal/student/studentrank.py", line 39, in get_raw_rank
    method=self.method,
  File "/home/nilekrator/.local/lib/python3.7/site-packages/pymysql/cursors.py", line 170, in execute
    result = self._query(query)
  File "/home/nilekrator/.local/lib/python3.7/site-packages/pymysql/cursors.py", line 328, in _query
    conn.query(q)
  File "/home/nilekrator/.local/lib/python3.7/site-packages/pymysql/connections.py", line 517, in query
    self._affected_rows = self._read_query_result(unbuffered=unbuffered)
  File "/home/nilekrator/.local/lib/python3.7/site-packages/pymysql/connections.py", line 732, in _read_query_result
    result.read()
  File "/home/nilekrator/.local/lib/python3.7/site-packages/pymysql/connections.py", line 1075, in read
    first_packet = self.connection._read_packet()
  File "/home/nilekrator/.local/lib/python3.7/site-packages/pymysql/connections.py", line 684, in _read_packet
    packet.check_error()
  File "/home/nilekrator/.local/lib/python3.7/site-packages/pymysql/protocol.py", line 220, in check_error
    err.raise_mysql_exception(self._data)
  File "/home/nilekrator/.local/lib/python3.7/site-packages/pymysql/err.py", line 109, in raise_mysql_exception
    raise errorclass(errno, errval)
pymysql.err.ProgrammingError: (1146, "Table 'nilekrator$_2018.UG_MM_5' doesn't exist")
2020-01-08 12:12:37,414: Exception on /rank [GET]
Traceback (most recent call last):
  File "/usr/lib/python3.7/site-packages/flask/app.py", line 2292, in wsgi_app
    response = self.full_dispatch_request()
  File "/usr/lib/python3.7/site-packages/flask/app.py", line 1815, in full_dispatch_request
    rv = self.handle_user_exception(e)
  File "/usr/lib/python3.7/site-packages/flask_restful/__init__.py", line 273, in error_router
    return original_handler(e)
  File "/usr/lib/python3.7/site-packages/flask/app.py", line 1718, in handle_user_exception
    reraise(exc_type, exc_value, tb)
  File "/usr/lib/python3.7/site-packages/flask/_compat.py", line 35, in reraise
    raise value
  File "/usr/lib/python3.7/site-packages/flask/app.py", line 1813, in full_dispatch_request
    rv = self.dispatch_request()
  File "/usr/lib/python3.7/site-packages/flask/app.py", line 1799, in dispatch_request
    return self.view_functions[rule.endpoint](**req.view_args)
  File "/home/nilekrator/resultportal/extensions.py", line 12, in decorated_function
    return f(*args, **kwargs)
  File "/home/nilekrator/resultportal/student/student.py", line 219, in rank
    Stu.get_raw_rank()
  File "/home/nilekrator/resultportal/student/studentrank.py", line 39, in get_raw_rank
    method=self.method,
  File "/home/nilekrator/.local/lib/python3.7/site-packages/pymysql/cursors.py", line 170, in execute
    result = self._query(query)
  File "/home/nilekrator/.local/lib/python3.7/site-packages/pymysql/cursors.py", line 328, in _query
    conn.query(q)
  File "/home/nilekrator/.local/lib/python3.7/site-packages/pymysql/connections.py", line 517, in query
    self._affected_rows = self._read_query_result(unbuffered=unbuffered)
  File "/home/nilekrator/.local/lib/python3.7/site-packages/pymysql/connections.py", line 732, in _read_query_result
    result.read()
  File "/home/nilekrator/.local/lib/python3.7/site-packages/pymysql/connections.py", line 1075, in read
    first_packet = self.connection._read_packet()
  File "/home/nilekrator/.local/lib/python3.7/site-packages/pymysql/connections.py", line 684, in _read_packet
    packet.check_error()
  File "/home/nilekrator/.local/lib/python3.7/site-packages/pymysql/protocol.py", line 220, in check_error
    err.raise_mysql_exception(self._data)
  File "/home/nilekrator/.local/lib/python3.7/site-packages/pymysql/err.py", line 109, in raise_mysql_exception
    raise errorclass(errno, errval)
pymysql.err.ProgrammingError: (1146, "Table 'nilekrator$_2019.UG_MM_5' doesn't exist")
2020-01-08 12:14:36,723: Exception on /rank [GET]
Traceback (most recent call last):
  File "/usr/lib/python3.7/site-packages/flask/app.py", line 2292, in wsgi_app
    response = self.full_dispatch_request()
  File "/usr/lib/python3.7/site-packages/flask/app.py", line 1815, in full_dispatch_request
    rv = self.handle_user_exception(e)
  File "/usr/lib/python3.7/site-packages/flask_restful/__init__.py", line 273, in error_router
    return original_handler(e)
  File "/usr/lib/python3.7/site-packages/flask/app.py", line 1718, in handle_user_exception
    reraise(exc_type, exc_value, tb)
  File "/usr/lib/python3.7/site-packages/flask/_compat.py", line 35, in reraise
    raise value
  File "/usr/lib/python3.7/site-packages/flask/app.py", line 1813, in full_dispatch_request
    rv = self.dispatch_request()
  File "/usr/lib/python3.7/site-packages/flask/app.py", line 1799, in dispatch_request
    return self.view_functions[rule.endpoint](**req.view_args)
  File "/home/nilekrator/resultportal/extensions.py", line 12, in decorated_function
    return f(*args, **kwargs)
  File "/home/nilekrator/resultportal/student/student.py", line 219, in rank
    Stu.get_raw_rank()
  File "/home/nilekrator/resultportal/student/studentrank.py", line 39, in get_raw_rank
    method=self.method,
  File "/home/nilekrator/.local/lib/python3.7/site-packages/pymysql/cursors.py", line 170, in execute
    result = self._query(query)
  File "/home/nilekrator/.local/lib/python3.7/site-packages/pymysql/cursors.py", line 328, in _query
    conn.query(q)
  File "/home/nilekrator/.local/lib/python3.7/site-packages/pymysql/connections.py", line 517, in query
    self._affected_rows = self._read_query_result(unbuffered=unbuffered)
  File "/home/nilekrator/.local/lib/python3.7/site-packages/pymysql/connections.py", line 732, in _read_query_result
    result.read()
  File "/home/nilekrator/.local/lib/python3.7/site-packages/pymysql/connections.py", line 1075, in read
    first_packet = self.connection._read_packet()
  File "/home/nilekrator/.local/lib/python3.7/site-packages/pymysql/connections.py", line 684, in _read_packet
    packet.check_error()
  File "/home/nilekrator/.local/lib/python3.7/site-packages/pymysql/protocol.py", line 220, in check_error
    err.raise_mysql_exception(self._data)
  File "/home/nilekrator/.local/lib/python3.7/site-packages/pymysql/err.py", line 109, in raise_mysql_exception
    raise errorclass(errno, errval)
pymysql.err.ProgrammingError: (1146, "Table 'nilekrator$_2019.UG_MM_5' doesn't exist")
2020-01-08 12:14:41,158: Exception on /rank [GET]
Traceback (most recent call last):
  File "/usr/lib/python3.7/site-packages/flask/app.py", line 2292, in wsgi_app
    response = self.full_dispatch_request()
  File "/usr/lib/python3.7/site-packages/flask/app.py", line 1815, in full_dispatch_request
    rv = self.handle_user_exception(e)
  File "/usr/lib/python3.7/site-packages/flask_restful/__init__.py", line 273, in error_router
    return original_handler(e)
  File "/usr/lib/python3.7/site-packages/flask/app.py", line 1718, in handle_user_exception
    reraise(exc_type, exc_value, tb)
  File "/usr/lib/python3.7/site-packages/flask/_compat.py", line 35, in reraise
    raise value
  File "/usr/lib/python3.7/site-packages/flask/app.py", line 1813, in full_dispatch_request
    rv = self.dispatch_request()
  File "/usr/lib/python3.7/site-packages/flask/app.py", line 1799, in dispatch_request
    return self.view_functions[rule.endpoint](**req.view_args)
  File "/home/nilekrator/resultportal/extensions.py", line 12, in decorated_function
    return f(*args, **kwargs)
  File "/home/nilekrator/resultportal/student/student.py", line 219, in rank
    Stu.get_raw_rank()
  File "/home/nilekrator/resultportal/student/studentrank.py", line 39, in get_raw_rank
    method=self.method,
  File "/home/nilekrator/.local/lib/python3.7/site-packages/pymysql/cursors.py", line 170, in execute
    result = self._query(query)
  File "/home/nilekrator/.local/lib/python3.7/site-packages/pymysql/cursors.py", line 328, in _query
    conn.query(q)
  File "/home/nilekrator/.local/lib/python3.7/site-packages/pymysql/connections.py", line 517, in query
    self._affected_rows = self._read_query_result(unbuffered=unbuffered)
  File "/home/nilekrator/.local/lib/python3.7/site-packages/pymysql/connections.py", line 732, in _read_query_result
    result.read()
  File "/home/nilekrator/.local/lib/python3.7/site-packages/pymysql/connections.py", line 1075, in read
    first_packet = self.connection._read_packet()
  File "/home/nilekrator/.local/lib/python3.7/site-packages/pymysql/connections.py", line 684, in _read_packet
    packet.check_error()
  File "/home/nilekrator/.local/lib/python3.7/site-packages/pymysql/protocol.py", line 220, in check_error
    err.raise_mysql_exception(self._data)
  File "/home/nilekrator/.local/lib/python3.7/site-packages/pymysql/err.py", line 109, in raise_mysql_exception
    raise errorclass(errno, errval)
pymysql.err.ProgrammingError: (1146, "Table 'nilekrator$_2019.UG_MM_5' doesn't exist")
2020-01-08 12:15:04,673: Exception on /rank [GET]
Traceback (most recent call last):
  File "/usr/lib/python3.7/site-packages/flask/app.py", line 2292, in wsgi_app
    response = self.full_dispatch_request()
  File "/usr/lib/python3.7/site-packages/flask/app.py", line 1815, in full_dispatch_request
    rv = self.handle_user_exception(e)
  File "/usr/lib/python3.7/site-packages/flask_restful/__init__.py", line 273, in error_router
    return original_handler(e)
  File "/usr/lib/python3.7/site-packages/flask/app.py", line 1718, in handle_user_exception
    reraise(exc_type, exc_value, tb)
  File "/usr/lib/python3.7/site-packages/flask/_compat.py", line 35, in reraise
    raise value
  File "/usr/lib/python3.7/site-packages/flask/app.py", line 1813, in full_dispatch_request
    rv = self.dispatch_request()
  File "/usr/lib/python3.7/site-packages/flask/app.py", line 1799, in dispatch_request
    return self.view_functions[rule.endpoint](**req.view_args)
  File "/home/nilekrator/resultportal/extensions.py", line 12, in decorated_function
    return f(*args, **kwargs)
  File "/home/nilekrator/resultportal/student/student.py", line 219, in rank
    Stu.get_raw_rank()
  File "/home/nilekrator/resultportal/student/studentrank.py", line 39, in get_raw_rank
    method=self.method,
  File "/home/nilekrator/.local/lib/python3.7/site-packages/pymysql/cursors.py", line 170, in execute
    result = self._query(query)
  File "/home/nilekrator/.local/lib/python3.7/site-packages/pymysql/cursors.py", line 328, in _query
    conn.query(q)
  File "/home/nilekrator/.local/lib/python3.7/site-packages/pymysql/connections.py", line 517, in query
    self._affected_rows = self._read_query_result(unbuffered=unbuffered)
  File "/home/nilekrator/.local/lib/python3.7/site-packages/pymysql/connections.py", line 732, in _read_query_result
    result.read()
  File "/home/nilekrator/.local/lib/python3.7/site-packages/pymysql/connections.py", line 1075, in read
    first_packet = self.connection._read_packet()
  File "/home/nilekrator/.local/lib/python3.7/site-packages/pymysql/connections.py", line 684, in _read_packet
    packet.check_error()
  File "/home/nilekrator/.local/lib/python3.7/site-packages/pymysql/protocol.py", line 220, in check_error
    err.raise_mysql_exception(self._data)
  File "/home/nilekrator/.local/lib/python3.7/site-packages/pymysql/err.py", line 109, in raise_mysql_exception
    raise errorclass(errno, errval)
pymysql.err.ProgrammingError: (1146, "Table 'nilekrator$_2018.UG_MM_5' doesn't exist")
2020-01-08 12:15:12,836: Exception on /rank [GET]
Traceback (most recent call last):
  File "/usr/lib/python3.7/site-packages/flask/app.py", line 2292, in wsgi_app
    response = self.full_dispatch_request()
  File "/usr/lib/python3.7/site-packages/flask/app.py", line 1815, in full_dispatch_request
    rv = self.handle_user_exception(e)
  File "/usr/lib/python3.7/site-packages/flask_restful/__init__.py", line 273, in error_router
    return original_handler(e)
  File "/usr/lib/python3.7/site-packages/flask/app.py", line 1718, in handle_user_exception
    reraise(exc_type, exc_value, tb)
  File "/usr/lib/python3.7/site-packages/flask/_compat.py", line 35, in reraise
    raise value
  File "/usr/lib/python3.7/site-packages/flask/app.py", line 1813, in full_dispatch_request
    rv = self.dispatch_request()
  File "/usr/lib/python3.7/site-packages/flask/app.py", line 1799, in dispatch_request
    return self.view_functions[rule.endpoint](**req.view_args)
  File "/home/nilekrator/resultportal/extensions.py", line 12, in decorated_function
    return f(*args, **kwargs)
  File "/home/nilekrator/resultportal/student/student.py", line 219, in rank
    Stu.get_raw_rank()
  File "/home/nilekrator/resultportal/student/studentrank.py", line 39, in get_raw_rank
    method=self.method,
  File "/home/nilekrator/.local/lib/python3.7/site-packages/pymysql/cursors.py", line 170, in execute
    result = self._query(query)
  File "/home/nilekrator/.local/lib/python3.7/site-packages/pymysql/cursors.py", line 328, in _query
    conn.query(q)
  File "/home/nilekrator/.local/lib/python3.7/site-packages/pymysql/connections.py", line 517, in query
    self._affected_rows = self._read_query_result(unbuffered=unbuffered)
  File "/home/nilekrator/.local/lib/python3.7/site-packages/pymysql/connections.py", line 732, in _read_query_result
    result.read()
  File "/home/nilekrator/.local/lib/python3.7/site-packages/pymysql/connections.py", line 1075, in read
    first_packet = self.connection._read_packet()
  File "/home/nilekrator/.local/lib/python3.7/site-packages/pymysql/connections.py", line 684, in _read_packet
    packet.check_error()
  File "/home/nilekrator/.local/lib/python3.7/site-packages/pymysql/protocol.py", line 220, in check_error
    err.raise_mysql_exception(self._data)
  File "/home/nilekrator/.local/lib/python3.7/site-packages/pymysql/err.py", line 109, in raise_mysql_exception
    raise errorclass(errno, errval)
pymysql.err.ProgrammingError: (1146, "Table 'nilekrator$_2018.UG_MM_5' doesn't exist")
2020-01-08 12:15:26,889: Exception on / [POST]
Traceback (most recent call last):
  File "/usr/lib/python3.7/site-packages/flask/app.py", line 2292, in wsgi_app
    response = self.full_dispatch_request()
  File "/usr/lib/python3.7/site-packages/flask/app.py", line 1815, in full_dispatch_request
    rv = self.handle_user_exception(e)
  File "/usr/lib/python3.7/site-packages/flask_restful/__init__.py", line 273, in error_router
    return original_handler(e)
  File "/usr/lib/python3.7/site-packages/flask/app.py", line 1718, in handle_user_exception
    reraise(exc_type, exc_value, tb)
  File "/usr/lib/python3.7/site-packages/flask/_compat.py", line 35, in reraise
    raise value
  File "/usr/lib/python3.7/site-packages/flask/app.py", line 1813, in full_dispatch_request
    rv = self.dispatch_request()
  File "/usr/lib/python3.7/site-packages/flask/app.py", line 1799, in dispatch_request
    return self.view_functions[rule.endpoint](**req.view_args)
  File "/home/nilekrator/resultportal/run.py", line 48, in login
    conn = mysql.connect()
  File "/home/nilekrator/.local/lib/python3.7/site-packages/flaskext/mysql.py", line 53, in connect
    return pymysql.connect(**self.connect_args)
  File "/home/nilekrator/.local/lib/python3.7/site-packages/pymysql/__init__.py", line 94, in Connect
    return Connection(*args, **kwargs)
  File "/home/nilekrator/.local/lib/python3.7/site-packages/pymysql/connections.py", line 325, in __init__
    self.connect()
  File "/home/nilekrator/.local/lib/python3.7/site-packages/pymysql/connections.py", line 599, in connect
    self._request_authentication()
  File "/home/nilekrator/.local/lib/python3.7/site-packages/pymysql/connections.py", line 861, in _request_authentication
    auth_packet = self._read_packet()
  File "/home/nilekrator/.local/lib/python3.7/site-packages/pymysql/connections.py", line 684, in _read_packet
    packet.check_error()
  File "/home/nilekrator/.local/lib/python3.7/site-packages/pymysql/protocol.py", line 220, in check_error
    err.raise_mysql_exception(self._data)
  File "/home/nilekrator/.local/lib/python3.7/site-packages/pymysql/err.py", line 109, in raise_mysql_exception
    raise errorclass(errno, errval)
pymysql.err.InternalError: (1226, "User 'nilekrator' has exceeded the 'max_user_connections' resource (current value: 6)")
2020-01-08 12:16:16,108: Exception on /rank [GET]
Traceback (most recent call last):
  File "/usr/lib/python3.7/site-packages/flask/app.py", line 2292, in wsgi_app
    response = self.full_dispatch_request()
  File "/usr/lib/python3.7/site-packages/flask/app.py", line 1815, in full_dispatch_request
    rv = self.handle_user_exception(e)
  File "/usr/lib/python3.7/site-packages/flask_restful/__init__.py", line 273, in error_router
    return original_handler(e)
  File "/usr/lib/python3.7/site-packages/flask/app.py", line 1718, in handle_user_exception
    reraise(exc_type, exc_value, tb)
  File "/usr/lib/python3.7/site-packages/flask/_compat.py", line 35, in reraise
    raise value
  File "/usr/lib/python3.7/site-packages/flask/app.py", line 1813, in full_dispatch_request
    rv = self.dispatch_request()
  File "/usr/lib/python3.7/site-packages/flask/app.py", line 1799, in dispatch_request
    return self.view_functions[rule.endpoint](**req.view_args)
  File "/home/nilekrator/resultportal/extensions.py", line 12, in decorated_function
    return f(*args, **kwargs)
  File "/home/nilekrator/resultportal/student/student.py", line 219, in rank
    Stu.get_raw_rank()
  File "/home/nilekrator/resultportal/student/studentrank.py", line 39, in get_raw_rank
    method=self.method,
  File "/home/nilekrator/.local/lib/python3.7/site-packages/pymysql/cursors.py", line 170, in execute
    result = self._query(query)
  File "/home/nilekrator/.local/lib/python3.7/site-packages/pymysql/cursors.py", line 328, in _query
    conn.query(q)
  File "/home/nilekrator/.local/lib/python3.7/site-packages/pymysql/connections.py", line 517, in query
    self._affected_rows = self._read_query_result(unbuffered=unbuffered)
  File "/home/nilekrator/.local/lib/python3.7/site-packages/pymysql/connections.py", line 732, in _read_query_result
    result.read()
  File "/home/nilekrator/.local/lib/python3.7/site-packages/pymysql/connections.py", line 1075, in read
    first_packet = self.connection._read_packet()
  File "/home/nilekrator/.local/lib/python3.7/site-packages/pymysql/connections.py", line 684, in _read_packet
    packet.check_error()
  File "/home/nilekrator/.local/lib/python3.7/site-packages/pymysql/protocol.py", line 220, in check_error
    err.raise_mysql_exception(self._data)
  File "/home/nilekrator/.local/lib/python3.7/site-packages/pymysql/err.py", line 109, in raise_mysql_exception
    raise errorclass(errno, errval)
pymysql.err.ProgrammingError: (1146, "Table 'nilekrator$_2019.UG_MM_5' doesn't exist")
2020-01-08 12:16:19,677: Exception on / [POST]
Traceback (most recent call last):
  File "/usr/lib/python3.7/site-packages/flask/app.py", line 2292, in wsgi_app
    response = self.full_dispatch_request()
  File "/usr/lib/python3.7/site-packages/flask/app.py", line 1815, in full_dispatch_request
    rv = self.handle_user_exception(e)
  File "/usr/lib/python3.7/site-packages/flask_restful/__init__.py", line 273, in error_router
    return original_handler(e)
  File "/usr/lib/python3.7/site-packages/flask/app.py", line 1718, in handle_user_exception
    reraise(exc_type, exc_value, tb)
  File "/usr/lib/python3.7/site-packages/flask/_compat.py", line 35, in reraise
    raise value
  File "/usr/lib/python3.7/site-packages/flask/app.py", line 1813, in full_dispatch_request
    rv = self.dispatch_request()
  File "/usr/lib/python3.7/site-packages/flask/app.py", line 1799, in dispatch_request
    return self.view_functions[rule.endpoint](**req.view_args)
  File "/home/nilekrator/resultportal/run.py", line 48, in login
    conn = mysql.connect()
  File "/home/nilekrator/.local/lib/python3.7/site-packages/flaskext/mysql.py", line 53, in connect
    return pymysql.connect(**self.connect_args)
  File "/home/nilekrator/.local/lib/python3.7/site-packages/pymysql/__init__.py", line 94, in Connect
    return Connection(*args, **kwargs)
  File "/home/nilekrator/.local/lib/python3.7/site-packages/pymysql/connections.py", line 325, in __init__
    self.connect()
  File "/home/nilekrator/.local/lib/python3.7/site-packages/pymysql/connections.py", line 599, in connect
    self._request_authentication()
  File "/home/nilekrator/.local/lib/python3.7/site-packages/pymysql/connections.py", line 861, in _request_authentication
    auth_packet = self._read_packet()
  File "/home/nilekrator/.local/lib/python3.7/site-packages/pymysql/connections.py", line 684, in _read_packet
    packet.check_error()
  File "/home/nilekrator/.local/lib/python3.7/site-packages/pymysql/protocol.py", line 220, in check_error
    err.raise_mysql_exception(self._data)
  File "/home/nilekrator/.local/lib/python3.7/site-packages/pymysql/err.py", line 109, in raise_mysql_exception
    raise errorclass(errno, errval)
pymysql.err.InternalError: (1226, "User 'nilekrator' has exceeded the 'max_user_connections' resource (current value: 6)")
2020-01-08 12:16:26,476: Exception on /rank [GET]
Traceback (most recent call last):
  File "/usr/lib/python3.7/site-packages/flask/app.py", line 2292, in wsgi_app
    response = self.full_dispatch_request()
  File "/usr/lib/python3.7/site-packages/flask/app.py", line 1815, in full_dispatch_request
    rv = self.handle_user_exception(e)
  File "/usr/lib/python3.7/site-packages/flask_restful/__init__.py", line 273, in error_router
    return original_handler(e)
  File "/usr/lib/python3.7/site-packages/flask/app.py", line 1718, in handle_user_exception
    reraise(exc_type, exc_value, tb)
  File "/usr/lib/python3.7/site-packages/flask/_compat.py", line 35, in reraise
    raise value
  File "/usr/lib/python3.7/site-packages/flask/app.py", line 1813, in full_dispatch_request
    rv = self.dispatch_request()
  File "/usr/lib/python3.7/site-packages/flask/app.py", line 1799, in dispatch_request
    return self.view_functions[rule.endpoint](**req.view_args)
  File "/home/nilekrator/resultportal/extensions.py", line 12, in decorated_function
    return f(*args, **kwargs)
  File "/home/nilekrator/resultportal/student/student.py", line 219, in rank
    Stu.get_raw_rank()
  File "/home/nilekrator/resultportal/student/studentrank.py", line 39, in get_raw_rank
    method=self.method,
  File "/home/nilekrator/.local/lib/python3.7/site-packages/pymysql/cursors.py", line 170, in execute
    result = self._query(query)
  File "/home/nilekrator/.local/lib/python3.7/site-packages/pymysql/cursors.py", line 328, in _query
    conn.query(q)
  File "/home/nilekrator/.local/lib/python3.7/site-packages/pymysql/connections.py", line 517, in query
    self._affected_rows = self._read_query_result(unbuffered=unbuffered)
  File "/home/nilekrator/.local/lib/python3.7/site-packages/pymysql/connections.py", line 732, in _read_query_result
    result.read()
  File "/home/nilekrator/.local/lib/python3.7/site-packages/pymysql/connections.py", line 1075, in read
    first_packet = self.connection._read_packet()
  File "/home/nilekrator/.local/lib/python3.7/site-packages/pymysql/connections.py", line 684, in _read_packet
    packet.check_error()
  File "/home/nilekrator/.local/lib/python3.7/site-packages/pymysql/protocol.py", line 220, in check_error
    err.raise_mysql_exception(self._data)
  File "/home/nilekrator/.local/lib/python3.7/site-packages/pymysql/err.py", line 109, in raise_mysql_exception
    raise errorclass(errno, errval)
pymysql.err.ProgrammingError: (1146, "Table 'nilekrator$_2019.UG_MM_5' doesn't exist")
2020-01-08 12:16:30,353: Exception on /rank [GET]
Traceback (most recent call last):
  File "/usr/lib/python3.7/site-packages/flask/app.py", line 2292, in wsgi_app
    response = self.full_dispatch_request()
  File "/usr/lib/python3.7/site-packages/flask/app.py", line 1815, in full_dispatch_request
    rv = self.handle_user_exception(e)
  File "/usr/lib/python3.7/site-packages/flask_restful/__init__.py", line 273, in error_router
    return original_handler(e)
  File "/usr/lib/python3.7/site-packages/flask/app.py", line 1718, in handle_user_exception
    reraise(exc_type, exc_value, tb)
  File "/usr/lib/python3.7/site-packages/flask/_compat.py", line 35, in reraise
    raise value
  File "/usr/lib/python3.7/site-packages/flask/app.py", line 1813, in full_dispatch_request
    rv = self.dispatch_request()
  File "/usr/lib/python3.7/site-packages/flask/app.py", line 1799, in dispatch_request
    return self.view_functions[rule.endpoint](**req.view_args)
  File "/home/nilekrator/resultportal/extensions.py", line 12, in decorated_function
    return f(*args, **kwargs)
  File "/home/nilekrator/resultportal/student/student.py", line 219, in rank
    Stu.get_raw_rank()
  File "/home/nilekrator/resultportal/student/studentrank.py", line 39, in get_raw_rank
    method=self.method,
  File "/home/nilekrator/.local/lib/python3.7/site-packages/pymysql/cursors.py", line 170, in execute
    result = self._query(query)
  File "/home/nilekrator/.local/lib/python3.7/site-packages/pymysql/cursors.py", line 328, in _query
    conn.query(q)
  File "/home/nilekrator/.local/lib/python3.7/site-packages/pymysql/connections.py", line 517, in query
    self._affected_rows = self._read_query_result(unbuffered=unbuffered)
  File "/home/nilekrator/.local/lib/python3.7/site-packages/pymysql/connections.py", line 732, in _read_query_result
    result.read()
  File "/home/nilekrator/.local/lib/python3.7/site-packages/pymysql/connections.py", line 1075, in read
    first_packet = self.connection._read_packet()
  File "/home/nilekrator/.local/lib/python3.7/site-packages/pymysql/connections.py", line 684, in _read_packet
    packet.check_error()
  File "/home/nilekrator/.local/lib/python3.7/site-packages/pymysql/protocol.py", line 220, in check_error
    err.raise_mysql_exception(self._data)
  File "/home/nilekrator/.local/lib/python3.7/site-packages/pymysql/err.py", line 109, in raise_mysql_exception
    raise errorclass(errno, errval)
pymysql.err.ProgrammingError: (1146, "Table 'nilekrator$_2019.UG_MM_5' doesn't exist")
2020-01-08 12:16:38,021: Exception on /rank [GET]
Traceback (most recent call last):
  File "/usr/lib/python3.7/site-packages/flask/app.py", line 2292, in wsgi_app
    response = self.full_dispatch_request()
  File "/usr/lib/python3.7/site-packages/flask/app.py", line 1815, in full_dispatch_request
    rv = self.handle_user_exception(e)
  File "/usr/lib/python3.7/site-packages/flask_restful/__init__.py", line 273, in error_router
    return original_handler(e)
  File "/usr/lib/python3.7/site-packages/flask/app.py", line 1718, in handle_user_exception
    reraise(exc_type, exc_value, tb)
  File "/usr/lib/python3.7/site-packages/flask/_compat.py", line 35, in reraise
    raise value
  File "/usr/lib/python3.7/site-packages/flask/app.py", line 1813, in full_dispatch_request
    rv = self.dispatch_request()
  File "/usr/lib/python3.7/site-packages/flask/app.py", line 1799, in dispatch_request
    return self.view_functions[rule.endpoint](**req.view_args)
  File "/home/nilekrator/resultportal/extensions.py", line 12, in decorated_function
    return f(*args, **kwargs)
  File "/home/nilekrator/resultportal/student/student.py", line 219, in rank
    Stu.get_raw_rank()
  File "/home/nilekrator/resultportal/student/studentrank.py", line 39, in get_raw_rank
    method=self.method,
  File "/home/nilekrator/.local/lib/python3.7/site-packages/pymysql/cursors.py", line 170, in execute
    result = self._query(query)
  File "/home/nilekrator/.local/lib/python3.7/site-packages/pymysql/cursors.py", line 328, in _query
    conn.query(q)
  File "/home/nilekrator/.local/lib/python3.7/site-packages/pymysql/connections.py", line 517, in query
    self._affected_rows = self._read_query_result(unbuffered=unbuffered)
  File "/home/nilekrator/.local/lib/python3.7/site-packages/pymysql/connections.py", line 732, in _read_query_result
    result.read()
  File "/home/nilekrator/.local/lib/python3.7/site-packages/pymysql/connections.py", line 1075, in read
    first_packet = self.connection._read_packet()
  File "/home/nilekrator/.local/lib/python3.7/site-packages/pymysql/connections.py", line 684, in _read_packet
    packet.check_error()
  File "/home/nilekrator/.local/lib/python3.7/site-packages/pymysql/protocol.py", line 220, in check_error
    err.raise_mysql_exception(self._data)
  File "/home/nilekrator/.local/lib/python3.7/site-packages/pymysql/err.py", line 109, in raise_mysql_exception
    raise errorclass(errno, errval)
pymysql.err.ProgrammingError: (1146, "Table 'nilekrator$_2019.UG_MM_5' doesn't exist")
2020-01-08 12:16:51,381: Exception on / [POST]
Traceback (most recent call last):
  File "/usr/lib/python3.7/site-packages/flask/app.py", line 2292, in wsgi_app
    response = self.full_dispatch_request()
  File "/usr/lib/python3.7/site-packages/flask/app.py", line 1815, in full_dispatch_request
    rv = self.handle_user_exception(e)
  File "/usr/lib/python3.7/site-packages/flask_restful/__init__.py", line 273, in error_router
    return original_handler(e)
  File "/usr/lib/python3.7/site-packages/flask/app.py", line 1718, in handle_user_exception
    reraise(exc_type, exc_value, tb)
  File "/usr/lib/python3.7/site-packages/flask/_compat.py", line 35, in reraise
    raise value
  File "/usr/lib/python3.7/site-packages/flask/app.py", line 1813, in full_dispatch_request
    rv = self.dispatch_request()
  File "/usr/lib/python3.7/site-packages/flask/app.py", line 1799, in dispatch_request
    return self.view_functions[rule.endpoint](**req.view_args)
  File "/home/nilekrator/resultportal/run.py", line 48, in login
    conn = mysql.connect()
  File "/home/nilekrator/.local/lib/python3.7/site-packages/flaskext/mysql.py", line 53, in connect
    return pymysql.connect(**self.connect_args)
  File "/home/nilekrator/.local/lib/python3.7/site-packages/pymysql/__init__.py", line 94, in Connect
    return Connection(*args, **kwargs)
  File "/home/nilekrator/.local/lib/python3.7/site-packages/pymysql/connections.py", line 325, in __init__
    self.connect()
  File "/home/nilekrator/.local/lib/python3.7/site-packages/pymysql/connections.py", line 599, in connect
    self._request_authentication()
  File "/home/nilekrator/.local/lib/python3.7/site-packages/pymysql/connections.py", line 861, in _request_authentication
    auth_packet = self._read_packet()
  File "/home/nilekrator/.local/lib/python3.7/site-packages/pymysql/connections.py", line 684, in _read_packet
    packet.check_error()
  File "/home/nilekrator/.local/lib/python3.7/site-packages/pymysql/protocol.py", line 220, in check_error
    err.raise_mysql_exception(self._data)
  File "/home/nilekrator/.local/lib/python3.7/site-packages/pymysql/err.py", line 109, in raise_mysql_exception
    raise errorclass(errno, errval)
pymysql.err.InternalError: (1226, "User 'nilekrator' has exceeded the 'max_user_connections' resource (current value: 6)")
2020-01-08 12:16:57,734: Exception on / [POST]
Traceback (most recent call last):
  File "/usr/lib/python3.7/site-packages/flask/app.py", line 2292, in wsgi_app
    response = self.full_dispatch_request()
  File "/usr/lib/python3.7/site-packages/flask/app.py", line 1815, in full_dispatch_request
    rv = self.handle_user_exception(e)
  File "/usr/lib/python3.7/site-packages/flask_restful/__init__.py", line 273, in error_router
    return original_handler(e)
  File "/usr/lib/python3.7/site-packages/flask/app.py", line 1718, in handle_user_exception
    reraise(exc_type, exc_value, tb)
  File "/usr/lib/python3.7/site-packages/flask/_compat.py", line 35, in reraise
    raise value
  File "/usr/lib/python3.7/site-packages/flask/app.py", line 1813, in full_dispatch_request
    rv = self.dispatch_request()
  File "/usr/lib/python3.7/site-packages/flask/app.py", line 1799, in dispatch_request
    return self.view_functions[rule.endpoint](**req.view_args)
  File "/home/nilekrator/resultportal/run.py", line 48, in login
    conn = mysql.connect()
  File "/home/nilekrator/.local/lib/python3.7/site-packages/flaskext/mysql.py", line 53, in connect
    return pymysql.connect(**self.connect_args)
  File "/home/nilekrator/.local/lib/python3.7/site-packages/pymysql/__init__.py", line 94, in Connect
    return Connection(*args, **kwargs)
  File "/home/nilekrator/.local/lib/python3.7/site-packages/pymysql/connections.py", line 325, in __init__
    self.connect()
  File "/home/nilekrator/.local/lib/python3.7/site-packages/pymysql/connections.py", line 599, in connect
    self._request_authentication()
  File "/home/nilekrator/.local/lib/python3.7/site-packages/pymysql/connections.py", line 861, in _request_authentication
    auth_packet = self._read_packet()
  File "/home/nilekrator/.local/lib/python3.7/site-packages/pymysql/connections.py", line 684, in _read_packet
    packet.check_error()
  File "/home/nilekrator/.local/lib/python3.7/site-packages/pymysql/protocol.py", line 220, in check_error
    err.raise_mysql_exception(self._data)
  File "/home/nilekrator/.local/lib/python3.7/site-packages/pymysql/err.py", line 109, in raise_mysql_exception
    raise errorclass(errno, errval)
pymysql.err.InternalError: (1226, "User 'nilekrator' has exceeded the 'max_user_connections' resource (current value: 6)")
2020-01-08 12:17:14,138: Exception on / [POST]
Traceback (most recent call last):
  File "/usr/lib/python3.7/site-packages/flask/app.py", line 2292, in wsgi_app
    response = self.full_dispatch_request()
  File "/usr/lib/python3.7/site-packages/flask/app.py", line 1815, in full_dispatch_request
    rv = self.handle_user_exception(e)
  File "/usr/lib/python3.7/site-packages/flask_restful/__init__.py", line 273, in error_router
    return original_handler(e)
  File "/usr/lib/python3.7/site-packages/flask/app.py", line 1718, in handle_user_exception
    reraise(exc_type, exc_value, tb)
  File "/usr/lib/python3.7/site-packages/flask/_compat.py", line 35, in reraise
    raise value
  File "/usr/lib/python3.7/site-packages/flask/app.py", line 1813, in full_dispatch_request
    rv = self.dispatch_request()
  File "/usr/lib/python3.7/site-packages/flask/app.py", line 1799, in dispatch_request
    return self.view_functions[rule.endpoint](**req.view_args)
  File "/home/nilekrator/resultportal/run.py", line 48, in login
    conn = mysql.connect()
  File "/home/nilekrator/.local/lib/python3.7/site-packages/flaskext/mysql.py", line 53, in connect
    return pymysql.connect(**self.connect_args)
  File "/home/nilekrator/.local/lib/python3.7/site-packages/pymysql/__init__.py", line 94, in Connect
    return Connection(*args, **kwargs)
  File "/home/nilekrator/.local/lib/python3.7/site-packages/pymysql/connections.py", line 325, in __init__
    self.connect()
  File "/home/nilekrator/.local/lib/python3.7/site-packages/pymysql/connections.py", line 599, in connect
    self._request_authentication()
  File "/home/nilekrator/.local/lib/python3.7/site-packages/pymysql/connections.py", line 861, in _request_authentication
    auth_packet = self._read_packet()
  File "/home/nilekrator/.local/lib/python3.7/site-packages/pymysql/connections.py", line 684, in _read_packet
    packet.check_error()
  File "/home/nilekrator/.local/lib/python3.7/site-packages/pymysql/protocol.py", line 220, in check_error
    err.raise_mysql_exception(self._data)
  File "/home/nilekrator/.local/lib/python3.7/site-packages/pymysql/err.py", line 109, in raise_mysql_exception
    raise errorclass(errno, errval)
pymysql.err.InternalError: (1226, "User 'nilekrator' has exceeded the 'max_user_connections' resource (current value: 6)")
2020-01-08 12:17:29,444: Exception on / [POST]
Traceback (most recent call last):
  File "/usr/lib/python3.7/site-packages/flask/app.py", line 2292, in wsgi_app
    response = self.full_dispatch_request()
  File "/usr/lib/python3.7/site-packages/flask/app.py", line 1815, in full_dispatch_request
    rv = self.handle_user_exception(e)
  File "/usr/lib/python3.7/site-packages/flask_restful/__init__.py", line 273, in error_router
    return original_handler(e)
  File "/usr/lib/python3.7/site-packages/flask/app.py", line 1718, in handle_user_exception
    reraise(exc_type, exc_value, tb)
  File "/usr/lib/python3.7/site-packages/flask/_compat.py", line 35, in reraise
    raise value
  File "/usr/lib/python3.7/site-packages/flask/app.py", line 1813, in full_dispatch_request
    rv = self.dispatch_request()
  File "/usr/lib/python3.7/site-packages/flask/app.py", line 1799, in dispatch_request
    return self.view_functions[rule.endpoint](**req.view_args)
  File "/home/nilekrator/resultportal/run.py", line 48, in login
    conn = mysql.connect()
  File "/home/nilekrator/.local/lib/python3.7/site-packages/flaskext/mysql.py", line 53, in connect
    return pymysql.connect(**self.connect_args)
  File "/home/nilekrator/.local/lib/python3.7/site-packages/pymysql/__init__.py", line 94, in Connect
    return Connection(*args, **kwargs)
  File "/home/nilekrator/.local/lib/python3.7/site-packages/pymysql/connections.py", line 325, in __init__
    self.connect()
  File "/home/nilekrator/.local/lib/python3.7/site-packages/pymysql/connections.py", line 599, in connect
    self._request_authentication()
  File "/home/nilekrator/.local/lib/python3.7/site-packages/pymysql/connections.py", line 861, in _request_authentication
    auth_packet = self._read_packet()
  File "/home/nilekrator/.local/lib/python3.7/site-packages/pymysql/connections.py", line 684, in _read_packet
    packet.check_error()
  File "/home/nilekrator/.local/lib/python3.7/site-packages/pymysql/protocol.py", line 220, in check_error
    err.raise_mysql_exception(self._data)
  File "/home/nilekrator/.local/lib/python3.7/site-packages/pymysql/err.py", line 109, in raise_mysql_exception
    raise errorclass(errno, errval)
pymysql.err.InternalError: (1226, "User 'nilekrator' has exceeded the 'max_user_connections' resource (current value: 6)")
2020-01-08 12:17:45,604: Exception on /rank [GET]
Traceback (most recent call last):
  File "/usr/lib/python3.7/site-packages/flask/app.py", line 2292, in wsgi_app
    response = self.full_dispatch_request()
  File "/usr/lib/python3.7/site-packages/flask/app.py", line 1815, in full_dispatch_request
    rv = self.handle_user_exception(e)
  File "/usr/lib/python3.7/site-packages/flask_restful/__init__.py", line 273, in error_router
    return original_handler(e)
  File "/usr/lib/python3.7/site-packages/flask/app.py", line 1718, in handle_user_exception
    reraise(exc_type, exc_value, tb)
  File "/usr/lib/python3.7/site-packages/flask/_compat.py", line 35, in reraise
    raise value
  File "/usr/lib/python3.7/site-packages/flask/app.py", line 1813, in full_dispatch_request
    rv = self.dispatch_request()
  File "/usr/lib/python3.7/site-packages/flask/app.py", line 1799, in dispatch_request
    return self.view_functions[rule.endpoint](**req.view_args)
  File "/home/nilekrator/resultportal/extensions.py", line 12, in decorated_function
    return f(*args, **kwargs)
  File "/home/nilekrator/resultportal/student/student.py", line 219, in rank
    Stu.get_raw_rank()
  File "/home/nilekrator/resultportal/student/studentrank.py", line 39, in get_raw_rank
    method=self.method,
  File "/home/nilekrator/.local/lib/python3.7/site-packages/pymysql/cursors.py", line 170, in execute
    result = self._query(query)
  File "/home/nilekrator/.local/lib/python3.7/site-packages/pymysql/cursors.py", line 328, in _query
    conn.query(q)
  File "/home/nilekrator/.local/lib/python3.7/site-packages/pymysql/connections.py", line 517, in query
    self._affected_rows = self._read_query_result(unbuffered=unbuffered)
  File "/home/nilekrator/.local/lib/python3.7/site-packages/pymysql/connections.py", line 732, in _read_query_result
    result.read()
  File "/home/nilekrator/.local/lib/python3.7/site-packages/pymysql/connections.py", line 1075, in read
    first_packet = self.connection._read_packet()
  File "/home/nilekrator/.local/lib/python3.7/site-packages/pymysql/connections.py", line 684, in _read_packet
    packet.check_error()
  File "/home/nilekrator/.local/lib/python3.7/site-packages/pymysql/protocol.py", line 220, in check_error
    err.raise_mysql_exception(self._data)
  File "/home/nilekrator/.local/lib/python3.7/site-packages/pymysql/err.py", line 109, in raise_mysql_exception
    raise errorclass(errno, errval)
pymysql.err.ProgrammingError: (1146, "Table 'nilekrator$_2019.UG_MM_5' doesn't exist")
2020-01-08 12:17:51,316: Exception on /rank [GET]
Traceback (most recent call last):
  File "/usr/lib/python3.7/site-packages/flask/app.py", line 2292, in wsgi_app
    response = self.full_dispatch_request()
  File "/usr/lib/python3.7/site-packages/flask/app.py", line 1815, in full_dispatch_request
    rv = self.handle_user_exception(e)
  File "/usr/lib/python3.7/site-packages/flask_restful/__init__.py", line 273, in error_router
    return original_handler(e)
  File "/usr/lib/python3.7/site-packages/flask/app.py", line 1718, in handle_user_exception
    reraise(exc_type, exc_value, tb)
  File "/usr/lib/python3.7/site-packages/flask/_compat.py", line 35, in reraise
    raise value
  File "/usr/lib/python3.7/site-packages/flask/app.py", line 1813, in full_dispatch_request
    rv = self.dispatch_request()
  File "/usr/lib/python3.7/site-packages/flask/app.py", line 1799, in dispatch_request
    return self.view_functions[rule.endpoint](**req.view_args)
  File "/home/nilekrator/resultportal/extensions.py", line 12, in decorated_function
    return f(*args, **kwargs)
  File "/home/nilekrator/resultportal/student/student.py", line 219, in rank
    Stu.get_raw_rank()
  File "/home/nilekrator/resultportal/student/studentrank.py", line 39, in get_raw_rank
    method=self.method,
  File "/home/nilekrator/.local/lib/python3.7/site-packages/pymysql/cursors.py", line 170, in execute
    result = self._query(query)
  File "/home/nilekrator/.local/lib/python3.7/site-packages/pymysql/cursors.py", line 328, in _query
    conn.query(q)
  File "/home/nilekrator/.local/lib/python3.7/site-packages/pymysql/connections.py", line 517, in query
    self._affected_rows = self._read_query_result(unbuffered=unbuffered)
  File "/home/nilekrator/.local/lib/python3.7/site-packages/pymysql/connections.py", line 732, in _read_query_result
    result.read()
  File "/home/nilekrator/.local/lib/python3.7/site-packages/pymysql/connections.py", line 1075, in read
    first_packet = self.connection._read_packet()
  File "/home/nilekrator/.local/lib/python3.7/site-packages/pymysql/connections.py", line 684, in _read_packet
    packet.check_error()
  File "/home/nilekrator/.local/lib/python3.7/site-packages/pymysql/protocol.py", line 220, in check_error
    err.raise_mysql_exception(self._data)
  File "/home/nilekrator/.local/lib/python3.7/site-packages/pymysql/err.py", line 109, in raise_mysql_exception
    raise errorclass(errno, errval)
pymysql.err.ProgrammingError: (1146, "Table 'nilekrator$_2019.UG_MM_5' doesn't exist")
2020-01-08 12:43:58,958: OSError: write error
2020-01-08 12:56:56,477: Exception on /rank [GET]
Traceback (most recent call last):
  File "/usr/lib/python3.7/site-packages/flask/app.py", line 2292, in wsgi_app
    response = self.full_dispatch_request()
  File "/usr/lib/python3.7/site-packages/flask/app.py", line 1815, in full_dispatch_request
    rv = self.handle_user_exception(e)
  File "/usr/lib/python3.7/site-packages/flask_restful/__init__.py", line 273, in error_router
    return original_handler(e)
  File "/usr/lib/python3.7/site-packages/flask/app.py", line 1718, in handle_user_exception
    reraise(exc_type, exc_value, tb)
  File "/usr/lib/python3.7/site-packages/flask/_compat.py", line 35, in reraise
    raise value
  File "/usr/lib/python3.7/site-packages/flask/app.py", line 1813, in full_dispatch_request
    rv = self.dispatch_request()
  File "/usr/lib/python3.7/site-packages/flask/app.py", line 1799, in dispatch_request
    return self.view_functions[rule.endpoint](**req.view_args)
  File "/home/nilekrator/resultportal/extensions.py", line 12, in decorated_function
    return f(*args, **kwargs)
  File "/home/nilekrator/resultportal/student/student.py", line 219, in rank
    Stu.get_raw_rank()
  File "/home/nilekrator/resultportal/student/studentrank.py", line 39, in get_raw_rank
    method=self.method,
  File "/home/nilekrator/.local/lib/python3.7/site-packages/pymysql/cursors.py", line 170, in execute
    result = self._query(query)
  File "/home/nilekrator/.local/lib/python3.7/site-packages/pymysql/cursors.py", line 328, in _query
    conn.query(q)
  File "/home/nilekrator/.local/lib/python3.7/site-packages/pymysql/connections.py", line 517, in query
    self._affected_rows = self._read_query_result(unbuffered=unbuffered)
  File "/home/nilekrator/.local/lib/python3.7/site-packages/pymysql/connections.py", line 732, in _read_query_result
    result.read()
  File "/home/nilekrator/.local/lib/python3.7/site-packages/pymysql/connections.py", line 1075, in read
    first_packet = self.connection._read_packet()
  File "/home/nilekrator/.local/lib/python3.7/site-packages/pymysql/connections.py", line 684, in _read_packet
    packet.check_error()
  File "/home/nilekrator/.local/lib/python3.7/site-packages/pymysql/protocol.py", line 220, in check_error
    err.raise_mysql_exception(self._data)
  File "/home/nilekrator/.local/lib/python3.7/site-packages/pymysql/err.py", line 109, in raise_mysql_exception
    raise errorclass(errno, errval)
pymysql.err.ProgrammingError: (1146, "Table 'nilekrator$_2018.UG_EE_5' doesn't exist")
2020-01-08 12:58:02,958: Retrying (Retry(total=2, connect=None, read=None, redirect=None, status=None)) after connection broken by 'SSLError(SSLEOFError(8, 'EOF occurred in violation of protocol (_ssl.c:1045)'))': /api/1471638/store/
2020-01-08 13:20:27,085: OSError: write error
2020-01-08 13:29:15,563: OSError: write error
2020-01-08 13:29:15,680: OSError: write error
2020-01-08 13:29:15,745: OSError: write error
2020-01-08 14:54:23,566: OSError: write error
2020-01-08 15:25:25,198: OSError: write error
2020-01-08 15:34:13,414: OSError: write error
2020-01-08 17:03:32,454: OSError: write error
2020-01-08 17:29:23,637: OSError: write error
2020-01-08 17:29:24,726: OSError: write error
2020-01-08 17:29:25,332: OSError: write error
2020-01-08 18:07:23,592: OSError: write error
2020-01-08 20:19:33,580: Exception on /rank [GET]
Traceback (most recent call last):
  File "/usr/lib/python3.7/site-packages/flask/app.py", line 2292, in wsgi_app
    response = self.full_dispatch_request()
  File "/usr/lib/python3.7/site-packages/flask/app.py", line 1815, in full_dispatch_request
    rv = self.handle_user_exception(e)
  File "/usr/lib/python3.7/site-packages/flask_restful/__init__.py", line 273, in error_router
    return original_handler(e)
  File "/usr/lib/python3.7/site-packages/flask/app.py", line 1718, in handle_user_exception
    reraise(exc_type, exc_value, tb)
  File "/usr/lib/python3.7/site-packages/flask/_compat.py", line 35, in reraise
    raise value
  File "/usr/lib/python3.7/site-packages/flask/app.py", line 1813, in full_dispatch_request
    rv = self.dispatch_request()
  File "/usr/lib/python3.7/site-packages/flask/app.py", line 1799, in dispatch_request
    return self.view_functions[rule.endpoint](**req.view_args)
  File "/home/nilekrator/resultportal/extensions.py", line 12, in decorated_function
    return f(*args, **kwargs)
  File "/home/nilekrator/resultportal/student/student.py", line 219, in rank
    Stu.get_raw_rank()
  File "/home/nilekrator/resultportal/student/studentrank.py", line 39, in get_raw_rank
    method=self.method,
  File "/home/nilekrator/.local/lib/python3.7/site-packages/pymysql/cursors.py", line 170, in execute
    result = self._query(query)
  File "/home/nilekrator/.local/lib/python3.7/site-packages/pymysql/cursors.py", line 328, in _query
    conn.query(q)
  File "/home/nilekrator/.local/lib/python3.7/site-packages/pymysql/connections.py", line 517, in query
    self._affected_rows = self._read_query_result(unbuffered=unbuffered)
  File "/home/nilekrator/.local/lib/python3.7/site-packages/pymysql/connections.py", line 732, in _read_query_result
    result.read()
  File "/home/nilekrator/.local/lib/python3.7/site-packages/pymysql/connections.py", line 1075, in read
    first_packet = self.connection._read_packet()
  File "/home/nilekrator/.local/lib/python3.7/site-packages/pymysql/connections.py", line 684, in _read_packet
    packet.check_error()
  File "/home/nilekrator/.local/lib/python3.7/site-packages/pymysql/protocol.py", line 220, in check_error
    err.raise_mysql_exception(self._data)
  File "/home/nilekrator/.local/lib/python3.7/site-packages/pymysql/err.py", line 109, in raise_mysql_exception
    raise errorclass(errno, errval)
pymysql.err.ProgrammingError: (1146, "Table 'nilekrator$_2019.UG_CS_3' doesn't exist")
2020-01-08 20:19:45,552: Exception on /rank [GET]
Traceback (most recent call last):
  File "/usr/lib/python3.7/site-packages/flask/app.py", line 2292, in wsgi_app
    response = self.full_dispatch_request()
  File "/usr/lib/python3.7/site-packages/flask/app.py", line 1815, in full_dispatch_request
    rv = self.handle_user_exception(e)
  File "/usr/lib/python3.7/site-packages/flask_restful/__init__.py", line 273, in error_router
    return original_handler(e)
  File "/usr/lib/python3.7/site-packages/flask/app.py", line 1718, in handle_user_exception
    reraise(exc_type, exc_value, tb)
  File "/usr/lib/python3.7/site-packages/flask/_compat.py", line 35, in reraise
    raise value
  File "/usr/lib/python3.7/site-packages/flask/app.py", line 1813, in full_dispatch_request
    rv = self.dispatch_request()
  File "/usr/lib/python3.7/site-packages/flask/app.py", line 1799, in dispatch_request
    return self.view_functions[rule.endpoint](**req.view_args)
  File "/home/nilekrator/resultportal/extensions.py", line 12, in decorated_function
    return f(*args, **kwargs)
  File "/home/nilekrator/resultportal/student/student.py", line 219, in rank
    Stu.get_raw_rank()
  File "/home/nilekrator/resultportal/student/studentrank.py", line 39, in get_raw_rank
    method=self.method,
  File "/home/nilekrator/.local/lib/python3.7/site-packages/pymysql/cursors.py", line 170, in execute
    result = self._query(query)
  File "/home/nilekrator/.local/lib/python3.7/site-packages/pymysql/cursors.py", line 328, in _query
    conn.query(q)
  File "/home/nilekrator/.local/lib/python3.7/site-packages/pymysql/connections.py", line 517, in query
    self._affected_rows = self._read_query_result(unbuffered=unbuffered)
  File "/home/nilekrator/.local/lib/python3.7/site-packages/pymysql/connections.py", line 732, in _read_query_result
    result.read()
  File "/home/nilekrator/.local/lib/python3.7/site-packages/pymysql/connections.py", line 1075, in read
    first_packet = self.connection._read_packet()
  File "/home/nilekrator/.local/lib/python3.7/site-packages/pymysql/connections.py", line 684, in _read_packet
    packet.check_error()
  File "/home/nilekrator/.local/lib/python3.7/site-packages/pymysql/protocol.py", line 220, in check_error
    err.raise_mysql_exception(self._data)
  File "/home/nilekrator/.local/lib/python3.7/site-packages/pymysql/err.py", line 109, in raise_mysql_exception
    raise errorclass(errno, errval)
pymysql.err.ProgrammingError: (1146, "Table 'nilekrator$_2019.UG_CS_3' doesn't exist")
2020-01-08 20:19:56,359: Exception on /rank [GET]
Traceback (most recent call last):
  File "/usr/lib/python3.7/site-packages/flask/app.py", line 2292, in wsgi_app
    response = self.full_dispatch_request()
  File "/usr/lib/python3.7/site-packages/flask/app.py", line 1815, in full_dispatch_request
    rv = self.handle_user_exception(e)
  File "/usr/lib/python3.7/site-packages/flask_restful/__init__.py", line 273, in error_router
    return original_handler(e)
  File "/usr/lib/python3.7/site-packages/flask/app.py", line 1718, in handle_user_exception
    reraise(exc_type, exc_value, tb)
  File "/usr/lib/python3.7/site-packages/flask/_compat.py", line 35, in reraise
    raise value
  File "/usr/lib/python3.7/site-packages/flask/app.py", line 1813, in full_dispatch_request
    rv = self.dispatch_request()
  File "/usr/lib/python3.7/site-packages/flask/app.py", line 1799, in dispatch_request
    return self.view_functions[rule.endpoint](**req.view_args)
  File "/home/nilekrator/resultportal/extensions.py", line 12, in decorated_function
    return f(*args, **kwargs)
  File "/home/nilekrator/resultportal/student/student.py", line 219, in rank
    Stu.get_raw_rank()
  File "/home/nilekrator/resultportal/student/studentrank.py", line 39, in get_raw_rank
    method=self.method,
  File "/home/nilekrator/.local/lib/python3.7/site-packages/pymysql/cursors.py", line 170, in execute
    result = self._query(query)
  File "/home/nilekrator/.local/lib/python3.7/site-packages/pymysql/cursors.py", line 328, in _query
    conn.query(q)
  File "/home/nilekrator/.local/lib/python3.7/site-packages/pymysql/connections.py", line 517, in query
    self._affected_rows = self._read_query_result(unbuffered=unbuffered)
  File "/home/nilekrator/.local/lib/python3.7/site-packages/pymysql/connections.py", line 732, in _read_query_result
    result.read()
  File "/home/nilekrator/.local/lib/python3.7/site-packages/pymysql/connections.py", line 1075, in read
    first_packet = self.connection._read_packet()
  File "/home/nilekrator/.local/lib/python3.7/site-packages/pymysql/connections.py", line 684, in _read_packet
    packet.check_error()
  File "/home/nilekrator/.local/lib/python3.7/site-packages/pymysql/protocol.py", line 220, in check_error
    err.raise_mysql_exception(self._data)
  File "/home/nilekrator/.local/lib/python3.7/site-packages/pymysql/err.py", line 109, in raise_mysql_exception
    raise errorclass(errno, errval)
pymysql.err.ProgrammingError: (1146, "Table 'nilekrator$_2019.UG_CS_3' doesn't exist")
2020-01-08 20:20:08,187: Exception on /rank [GET]
Traceback (most recent call last):
  File "/usr/lib/python3.7/site-packages/flask/app.py", line 2292, in wsgi_app
    response = self.full_dispatch_request()
  File "/usr/lib/python3.7/site-packages/flask/app.py", line 1815, in full_dispatch_request
    rv = self.handle_user_exception(e)
  File "/usr/lib/python3.7/site-packages/flask_restful/__init__.py", line 273, in error_router
    return original_handler(e)
  File "/usr/lib/python3.7/site-packages/flask/app.py", line 1718, in handle_user_exception
    reraise(exc_type, exc_value, tb)
  File "/usr/lib/python3.7/site-packages/flask/_compat.py", line 35, in reraise
    raise value
  File "/usr/lib/python3.7/site-packages/flask/app.py", line 1813, in full_dispatch_request
    rv = self.dispatch_request()
  File "/usr/lib/python3.7/site-packages/flask/app.py", line 1799, in dispatch_request
    return self.view_functions[rule.endpoint](**req.view_args)
  File "/home/nilekrator/resultportal/extensions.py", line 12, in decorated_function
    return f(*args, **kwargs)
  File "/home/nilekrator/resultportal/student/student.py", line 219, in rank
    Stu.get_raw_rank()
  File "/home/nilekrator/resultportal/student/studentrank.py", line 39, in get_raw_rank
    method=self.method,
  File "/home/nilekrator/.local/lib/python3.7/site-packages/pymysql/cursors.py", line 170, in execute
    result = self._query(query)
  File "/home/nilekrator/.local/lib/python3.7/site-packages/pymysql/cursors.py", line 328, in _query
    conn.query(q)
  File "/home/nilekrator/.local/lib/python3.7/site-packages/pymysql/connections.py", line 517, in query
    self._affected_rows = self._read_query_result(unbuffered=unbuffered)
  File "/home/nilekrator/.local/lib/python3.7/site-packages/pymysql/connections.py", line 732, in _read_query_result
    result.read()
  File "/home/nilekrator/.local/lib/python3.7/site-packages/pymysql/connections.py", line 1075, in read
    first_packet = self.connection._read_packet()
  File "/home/nilekrator/.local/lib/python3.7/site-packages/pymysql/connections.py", line 684, in _read_packet
    packet.check_error()
  File "/home/nilekrator/.local/lib/python3.7/site-packages/pymysql/protocol.py", line 220, in check_error
    err.raise_mysql_exception(self._data)
  File "/home/nilekrator/.local/lib/python3.7/site-packages/pymysql/err.py", line 109, in raise_mysql_exception
    raise errorclass(errno, errval)
pymysql.err.ProgrammingError: (1146, "Table 'nilekrator$_2019.UG_CS_3' doesn't exist")
2020-01-09 03:35:54,944: OSError: write error
2020-01-09 04:23:52,652: OSError: write error
2020-01-09 04:50:47,709: OSError: write error
2020-01-09 04:50:49,003: OSError: write error
2020-01-09 06:00:48,048: OSError: write error
2020-01-09 06:00:48,649: OSError: write error
2020-01-09 06:00:48,686: OSError: write error
2020-01-09 06:00:49,493: OSError: write error
2020-01-09 06:01:02,333: OSError: write error
2020-01-09 06:01:05,019: OSError: write error
2020-01-09 06:01:09,563: OSError: write error
2020-01-09 08:04:44,640: OSError: write error
2020-01-09 08:23:54,594: OSError: write error
2020-01-09 09:11:07,892: OSError: write error
